Workbook

Sheet 使い方
B2: 工事工程表アプリ(Excel版) の使い方
B4: ■ 仕組み | C4: 作業の入力は「工程マスタ」シート1か所だけ。全体工程表(月単位)・月間工程表(日単位)・日割り工程表(日単位詳細)は、すべて工程マスタから数式で自動生成されます。
B6: ① 設定 | C6: 工事名・工期・全体工程表の表示開始月・祝日リスト・工種リストを入力します。
B7: ② 工程マスタ | C7: 作業ごとに 工種/作業名/担当業者/開始日/終了日/進捗率 を入力します(最大150行)。マイルストーン(着工・上棟・検査・竣工など)は開始日=終了日にして「MS」列に○を入れると、工程表上に赤い▼で表示されます。
B8: ③ 全体工程表 | C8: 自動生成。表示開始月は「設定」シートで変更できます(24か月表示)。最下部に予定出来高曲線(自動計算)と実績出来高の入力行(黄色)があり、グラフに赤=予定/青=実績の2本のS字カーブを表示します。実績は毎月末に累計%を入力してください。
B9: ④ 月間工程表 | C9: 黄色セルで対象の年・月を選ぶと、その月に掛かる作業だけを自動抽出して日単位のガントを表示します。
B10: ⑤ 日割り工程表 | C10: 黄色セルに基準日を入力すると、その日から14日間の日別工程と日ごとの稼働作業数を表示します。
B11: ⑥ ネットワーク工程表 | C11: 工程マスタの「先行1〜3」列に先行作業のNo(自分より小さいNoのみ)を入力すると、CPM(クリティカルパス法)で最早開始/完了・最遅開始/完了・余裕日数を自動計算し、週単位のタイムラインに自動配置します。赤=クリティカルパス(遅らせると竣工が遅れる作業)、青=余裕のある作業、黄=フロート(遅らせられる幅)、数字=作業No。先行のない作業は工期(自)を開始日として計算します。不正な先行Noは工程マスタ上で赤く警告されます。
B13: ■ バーの見方 | C13: 水色=予定 / 濃青=進捗率に応じた実績(完了分) / 赤▼=マイルストーン / 黄色列=本日
B14: ■ 土日祝 | C14: 月間・日割り工程表では 土曜=青系、日曜・祝日=赤系 に自動で色分けされます。祝日は「設定」シートのリストを編集してください。
B16: ■ セルの色 | C16: 黄色セル=入力する場所 / 灰色セル=自動計算(触らない) / 白セルの表部分=自動生成
B17: ■ 注意 | C17: 全体工程表の表示は100行、月間・日割り工程表は各50行までです。行の挿入・削除はせず、工程マスタの空き行に追記してください。
B19: 凡例: | C19: 予定バー
C20: 実績バー

Sheet 設定
A1: 設定
A3: 工事名 | B3: (仮称)○○ビル新築工事 | D3: 祝日リスト(編集可) | H3: 工種リスト(編集可)
A4: 発注者 | B4: ○○株式会社 | D4: 日付 | E4: 名称
A5: 元請 | B5: △△建設株式会社 | D5: 46023 | E5: 元日 | H5: 仮設工事
A6: 現場代理人 | B6: 山田 太郎 | D6: 46034 | E6: 成人の日 | H6: 土工事・山留
D7: 46064 | E7: 建国記念の日 | H7: 地業基礎工事
A8: 工期(自) | B8: 46204 | D8: 46076 | E8: 天皇誕生日 | H8: 躯体工事
A9: 工期(至) | B9: 46477 | D9: 46101 | E9: 春分の日 | H9: 外装工事
D10: 46141 | E10: 昭和の日 | H10: 内装・設備工事
A11: 全体工程表 | D11: 46145 | E11: 憲法記念日 | H11: 外構工事
A12: 表示開始月 | B12: =DATE(YEAR($B$8),MONTH($B$8),1) -> 46204 | D12: 46146 | E12: みどりの日 | H12: 検査・引渡
A13: (24か月表示) | D13: 46147 | E13: こどもの日 | H13: マイルストーン
D14: 46148 | E14: 振替休日 | H14: その他
D15: 46223 | E15: 海の日
D16: 46245 | E16: 山の日
D17: 46286 | E17: 敬老の日
D18: 46287 | E18: 国民の休日
D19: 46288 | E19: 秋分の日
D20: 46307 | E20: スポーツの日
D21: 46329 | E21: 文化の日
D22: 46349 | E22: 勤労感謝の日
D23: 46388 | E23: 元日
D24: 46398 | E24: 成人の日
D25: 46429 | E25: 建国記念の日
D26: 46441 | E26: 天皇誕生日
... D38: 46714 | E38: 勤労感謝の日
D60: ※行 D5:D60 が判定対象

Sheet 工程マスタ
A1: 工程マスタ(作業の入力はこのシートだけ)
A2: 黄色列に入力 → 全体/月間/日割り/ネットワーク工程表へ自動反映。マイルストーンは開始日=終了日+MS列○。先行1〜3にはその作業より前に行う作業のNo(自分より小さいNoのみ)を入力。
A4: No | B4: 工種 | C4: 作業名 | D4: 担当業者 | E4: 開始日 | F4: 終了日 | G4: 日数 | H4: 進捗率 | I4: MS | J4: 備考 | K4: (開始) | L4: (終了) | M4: (実績境界) | N4: 先行1 | O4: 先行2 | P4: 先行3
A5: =IF($C5="","",ROW()-4) -> 1 | B5: マイルストーン | C5: 着工 | E5: 46204 | F5: 46204 | G5: =IF(OR($E5="",$F5=""),0,$F5-$E5+1) -> 1 | I5: ○ | K5: =IF($E5="",0,$E5) -> 46204 | L5: =IF($F5="",0,$F5) -> 46204 | M5: =IF(OR($G5=0,$H5=""),$K5,MIN($L5+1,$K5+$G5*$H5)) -> 46204
A6: =IF($C6="","",ROW()-4) -> 2 | B6: マイルストーン | C6: 地鎮祭・安全祈願祭 | E6: 46207 | F6: 46207 | G6: =IF(OR($E6="",$F6=""),0,$F6-$E6+1) -> 1 | I6: ○ | K6: =IF($E6="",0,$E6) -> 46207 | L6: =IF($F6="",0,$F6) -> 46207 | M6: =IF(OR($G6=0,$H6=""),$K6,MIN($L6+1,$K6+$G6*$H6)) -> 46207 | N6: 1
A7: =IF($C7="","",ROW()-4) -> 3 | B7: 仮設工事 | C7: 仮囲い・ゲート設置 | D7: ○○仮設工業 | E7: 46204 | F7: 46213 | G7: =IF(OR($E7="",$F7=""),0,$F7-$E7+1) -> 10 | H7: 1 | K7: =IF($E7="",0,$E7) -> 46204 | L7: =IF($F7="",0,$F7) -> 46213 | M7: =IF(OR($G7=0,$H7=""),$K7,MIN($L7+1,$K7+$G7*$H7)) -> 46214 | N7: 1
A8: =IF($C8="","",ROW()-4) -> 4 | B8: 仮設工事 | C8: 現場事務所・休憩所設置 | D8: ○○仮設工業 | E8: 46209 | F8: 46218 | G8: =IF(OR($E8="",$F8=""),0,$F8-$E8+1) -> 10 | H8: 1 | K8: =IF($E8="",0,$E8) -> 46209 | L8: =IF($F8="",0,$F8) -> 46218 | M8: =IF(OR($G8=0,$H8=""),$K8,MIN($L8+1,$K8+$G8*$H8)) -> 46219 | N8: 3
A9: =IF($C9="","",ROW()-4) -> 5 | B9: 仮設工事 | C9: 仮設電気・給排水引込み | D9: △△電設 | E9: 46216 | F9: 46225 | G9: =IF(OR($E9="",$F9=""),0,$F9-$E9+1) -> 10 | H9: 0.6 | K9: =IF($E9="",0,$E9) -> 46216 | L9: =IF($F9="",0,$F9) -> 46225 | M9: =IF(OR($G9=0,$H9=""),$K9,MIN($L9+1,$K9+$G9*$H9)) -> 46222 | N9: 4
A10: =IF($C10="","",ROW()-4) -> 6 | B10: 地業基礎工事 | C10: 杭工事 | D10: □□基礎工業 | E10: 46216 | F10: 46234 | G10: =IF(OR($E10="",$F10=""),0,$F10-$E10+1) -> 19 | H10: 0.35 | J10: 既製杭 | K10: =IF($E10="",0,$E10) -> 46216 | L10: =IF($F10="",0,$F10) -> 46234 | M10: =IF(OR($G10=0,$H10=""),$K10,MIN($L10+1,$K10+$G10*$H10)) -> 46222.65 | N10: 2 | O10: 3 | P10: 5
A11: =IF($C11="","",ROW()-4) -> 7 | B11: 土工事・山留 | C11: 山留工事 | D11: ▲▲土木 | E11: 46230 | F11: 46242 | G11: =IF(OR($E11="",$F11=""),0,$F11-$E11+1) -> 13 | H11: 0 | K11: =IF($E11="",0,$E11) -> 46230 | L11: =IF($F11="",0,$F11) -> 46242 | M11: =IF(OR($G11=0,$H11=""),$K11,MIN($L11+1,$K11+$G11*$H11)) -> 46230 | N11: 6
A12: =IF($C12="","",ROW()-4) -> 8 | B12: 土工事・山留 | C12: 根切り・掘削 | D12: ▲▲土木 | E12: 46237 | F12: 46259 | G12: =IF(OR($E12="",$F12=""),0,$F12-$E12+1) -> 23 | H12: 0 | K12: =IF($E12="",0,$E12) -> 46237 | L12: =IF($F12="",0,$F12) -> 46259 | M12: =IF(OR($G12=0,$H12=""),$K12,MIN($L12+1,$K12+$G12*$H12)) -> 46237 | N12: 7
A13: =IF($C13="","",ROW()-4) -> 9 | B13: 土工事・山留 | C13: 床付け・捨てコンクリート | D13: ▲▲土木 | E13: 46258 | F13: 46263 | G13: =IF(OR($E13="",$F13=""),0,$F13-$E13+1) -> 6 | H13: 0 | K13: =IF($E13="",0,$E13) -> 46258 | L13: =IF($F13="",0,$F13) -> 46263 | M13: =IF(OR($G13=0,$H13=""),$K13,MIN($L13+1,$K13+$G13*$H13)) -> 46258 | N13: 8
A14: =IF($C14="","",ROW()-4) -> 10 | B14: 地業基礎工事 | C14: 基礎配筋・型枠 | D14: ◇◇建設 | E14: 46265 | F14: 46277 | G14: =IF(OR($E14="",$F14=""),0,$F14-$E14+1) -> 13 | H14: 0 | J14: 配筋検査 9/9 | K14: =IF($E14="",0,$E14) -> 46265 | L14: =IF($F14="",0,$F14) -> 46277 | M14: =IF(OR($G14=0,$H14=""),$K14,MIN($L14+1,$K14+$G14*$H14)) -> 46265 | N14: 9
A15: =IF($C15="","",ROW()-4) -> 11 | B15: 地業基礎工事 | C15: 基礎コンクリート打設 | D15: ◇◇建設 | E15: 46279 | F15: 46281 | G15: =IF(OR($E15="",$F15=""),0,$F15-$E15+1) -> 3 | H15: 0 | K15: =IF($E15="",0,$E15) -> 46279 | L15: =IF($F15="",0,$F15) -> 46281 | M15: =IF(OR($G15=0,$H15=""),$K15,MIN($L15+1,$K15+$G15*$H15)) -> 46279 | N15: 10
A16: =IF($C16="","",ROW()-4) -> 12 | B16: 地業基礎工事 | C16: 養生・埋戻し | D16: ▲▲土木 | E16: 46282 | F16: 46291 | G16: =IF(OR($E16="",$F16=""),0,$F16-$E16+1) -> 10 | H16: 0 | K16: =IF($E16="",0,$E16) -> 46282 | L16: =IF($F16="",0,$F16) -> 46291 | M16: =IF(OR($G16=0,$H16=""),$K16,MIN($L16+1,$K16+$G16*$H16)) -> 46282 | N16: 11
A17: =IF($C17="","",ROW()-4) -> 13 | B17: 躯体工事 | C17: 鉄骨製作(工場) | D17: ☆☆鉄工所 | E17: 46237 | F17: 46290 | G17: =IF(OR($E17="",$F17=""),0,$F17-$E17+1) -> 54 | H17: 0 | J17: 製品検査 9/18 | K17: =IF($E17="",0,$E17) -> 46237 | L17: =IF($F17="",0,$F17) -> 46290 | M17: =IF(OR($G17=0,$H17=""),$K17,MIN($L17+1,$K17+$G17*$H17)) -> 46237 | N17: 2
A18: =IF($C18="","",ROW()-4) -> 14 | B18: マイルストーン | C18: 鉄骨建方開始 | E18: 46293 | F18: 46293 | G18: =IF(OR($E18="",$F18=""),0,$F18-$E18+1) -> 1 | I18: ○ | K18: =IF($E18="",0,$E18) -> 46293 | L18: =IF($F18="",0,$F18) -> 46293 | M18: =IF(OR($G18=0,$H18=""),$K18,MIN($L18+1,$K18+$G18*$H18)) -> 46293 | N18: 12 | O18: 13
A19: =IF($C19="","",ROW()-4) -> 15 | B19: 仮設工事 | C19: 外部足場組立 | D19: ○○仮設工業 | E19: 46289 | F19: 46301 | G19: =IF(OR($E19="",$F19=""),0,$F19-$E19+1) -> 13 | H19: 0 | K19: =IF($E19="",0,$E19) -> 46289 | L19: =IF($F19="",0,$F19) -> 46301 | M19: =IF(OR($G19=0,$H19=""),$K19,MIN($L19+1,$K19+$G19*$H19)) -> 46289 | N19: 12
A20: =IF($C20="","",ROW()-4) -> 16 | B20: 躯体工事 | C20: 鉄骨建方 | D20: ☆☆鉄工所 | E20: 46293 | F20: 46318 | G20: =IF(OR($E20="",$F20=""),0,$F20-$E20+1) -> 26 | H20: 0 | K20: =IF($E20="",0,$E20) -> 46293 | L20: =IF($F20="",0,$F20) -> 46318 | M20: =IF(OR($G20=0,$H20=""),$K20,MIN($L20+1,$K20+$G20*$H20)) -> 46293 | N20: 14 | O20: 15
A21: =IF($C21="","",ROW()-4) -> 17 | B21: マイルストーン | C21: 上棟 | E21: 46318 | F21: 46318 | G21: =IF(OR($E21="",$F21=""),0,$F21-$E21+1) -> 1 | I21: ○ | K21: =IF($E21="",0,$E21) -> 46318 | L21: =IF($F21="",0,$F21) -> 46318 | M21: =IF(OR($G21=0,$H21=""),$K21,MIN($L21+1,$K21+$G21*$H21)) -> 46318 | N21: 16
A22: =IF($C22="","",ROW()-4) -> 18 | B22: 躯体工事 | C22: 本締め・建入れ検査 | D22: ☆☆鉄工所 | E22: 46321 | F22: 46332 | G22: =IF(OR($E22="",$F22=""),0,$F22-$E22+1) -> 12 | H22: 0 | K22: =IF($E22="",0,$E22) -> 46321 | L22: =IF($F22="",0,$F22) -> 46332 | M22: =IF(OR($G22=0,$H22=""),$K22,MIN($L22+1,$K22+$G22*$H22)) -> 46321 | N22: 17
A23: =IF($C23="","",ROW()-4) -> 19 | B23: 躯体工事 | C23: デッキ・スタッド溶接 | D23: ☆☆鉄工所 | E23: 46314 | F23: 46339 | G23: =IF(OR($E23="",$F23=""),0,$F23-$E23+1) -> 26 | H23: 0 | K23: =IF($E23="",0,$E23) -> 46314 | L23: =IF($F23="",0,$F23) -> 46339 | M23: =IF(OR($G23=0,$H23=""),$K23,MIN($L23+1,$K23+$G23*$H23)) -> 46314 | N23: 17
A24: =IF($C24="","",ROW()-4) -> 20 | B24: 躯体工事 | C24: 床コンクリート打設 | D24: ◇◇建設 | E24: 46335 | F24: 46353 | G24: =IF(OR($E24="",$F24=""),0,$F24-$E24+1) -> 19 | H24: 0 | K24: =IF($E24="",0,$E24) -> 46335 | L24: =IF($F24="",0,$F24) -> 46353 | M24: =IF(OR($G24=0,$H24=""),$K24,MIN($L24+1,$K24+$G24*$H24)) -> 46335 | N24: 18 | O24: 19
A25: =IF($C25="","",ROW()-4) -> 21 | B25: 外装工事 | C25: 屋根・屋上防水 | D25: ●●防水 | E25: 46350 | F25: 46374 | G25: =IF(OR($E25="",$F25=""),0,$F25-$E25+1) -> 25 | H25: 0 | K25: =IF($E25="",0,$E25) -> 46350 | L25: =IF($F25="",0,$F25) -> 46374 | M25: =IF(OR($G25=0,$H25=""),$K25,MIN($L25+1,$K25+$G25*$H25)) -> 46350 | N25: 20
A26: =IF($C26="","",ROW()-4) -> 22 | B26: 外装工事 | C26: 外壁下地・胴縁 | D26: ■■外装 | E26: 46342 | F26: 46360 | G26: =IF(OR($E26="",$F26=""),0,$F26-$E26+1) -> 19 | H26: 0 | K26: =IF($E26="",0,$E26) -> 46342 | L26: =IF($F26="",0,$F26) -> 46360 | M26: =IF(OR($G26=0,$H26=""),$K26,MIN($L26+1,$K26+$G26*$H26)) -> 46342 | N26: 20
A27: =IF($C27="","",ROW()-4) -> 23 | B27: 外装工事 | C27: 外壁パネル(ALC)取付 | D27: ■■外装 | E27: 46356 | F27: 46381 | G27: =IF(OR($E27="",$F27=""),0,$F27-$E27+1) -> 26 | H27: 0 | K27: =IF($E27="",0,$E27) -> 46356 | L27: =IF($F27="",0,$F27) -> 46381 | M27: =IF(OR($G27=0,$H27=""),$K27,MIN($L27+1,$K27+$G27*$H27)) -> 46356 | N27: 22
A28: =IF($C28="","",ROW()-4) -> 24 | B28: 外装工事 | C28: サッシ・外部建具取付 | D28: ▽▽サッシ | E28: 46370 | F28: 46395 | G28: =IF(OR($E28="",$F28=""),0,$F28-$E28+1) -> 26 | H28: 0 | K28: =IF($E28="",0,$E28) -> 46370 | L28: =IF($F28="",0,$F28) -> 46395 | M28: =IF(OR($G28=0,$H28=""),$K28,MIN($L28+1,$K28+$G28*$H28)) -> 46370 | N28: 23
A29: =IF($C29="","",ROW()-4) -> 25 | B29: 外装工事 | C29: シール・外部防水 | D29: ●●防水 | E29: 46392 | F29: 46409 | G29: =IF(OR($E29="",$F29=""),0,$F29-$E29+1) -> 18 | H29: 0 | K29: =IF($E29="",0,$E29) -> 46392 | L29: =IF($F29="",0,$F29) -> 46409 | M29: =IF(OR($G29=0,$H29=""),$K29,MIN($L29+1,$K29+$G29*$H29)) -> 46392 | N29: 24
A30: =IF($C30="","",ROW()-4) -> 26 | B30: 外装工事 | C30: 外壁塗装・仕上 | D30: ■■外装 | E30: 46405 | F30: 46423 | G30: =IF(OR($E30="",$F30=""),0,$F30-$E30+1) -> 19 | H30: 0 | K30: =IF($E30="",0,$E30) -> 46405 | L30: =IF($F30="",0,$F30) -> 46423 | M30: =IF(OR($G30=0,$H30=""),$K30,MIN($L30+1,$K30+$G30*$H30)) -> 46405 | N30: 25
A31: =IF($C31="","",ROW()-4) -> 27 | B31: マイルストーン | C31: 外部足場解体 | E31: 46412 | F31: 46412 | G31: =IF(OR($E31="",$F31=""),0,$F31-$E31+1) -> 1 | I31: ○ | K31: =IF($E31="",0,$E31) -> 46412 | L31: =IF($F31="",0,$F31) -> 46412 | M31: =IF(OR($G31=0,$H31=""),$K31,MIN($L31+1,$K31+$G31*$H31)) -> 46412 | N31: 26
A32: =IF($C32="","",ROW()-4) -> 28 | B32: 仮設工事 | C32: 外部足場解体 | D32: ○○仮設工業 | E32: 46412 | F32: 46417 | G32: =IF(OR($E32="",$F32=""),0,$F32-$E32+1) -> 6 | H32: 0 | K32: =IF($E32="",0,$E32) -> 46412 | L32: =IF($F32="",0,$F32) -> 46417 | M32: =IF(OR($G32=0,$H32=""),$K32,MIN($L32+1,$K32+$G32*$H32)) -> 46412 | N32: 27
A33: =IF($C33="","",ROW()-4) -> 29 | B33: 内装・設備工事 | C33: 設備配管・配線(隠蔽部) | D33: △△電設・◎◎設備 | E33: 46342 | F33: 46403 | G33: =IF(OR($E33="",$F33=""),0,$F33-$E33+1) -> 62 | H33: 0 | K33: =IF($E33="",0,$E33) -> 46342 | L33: =IF($F33="",0,$F33) -> 46403 | M33: =IF(OR($G33=0,$H33=""),$K33,MIN($L33+1,$K33+$G33*$H33)) -> 46342 | N33: 20
A34: =IF($C34="","",ROW()-4) -> 30 | B34: 内装・設備工事 | C34: 天井・壁LGS下地 | D34: ☆☆内装 | E34: 46377 | F34: 46416 | G34: =IF(OR($E34="",$F34=""),0,$F34-$E34+1) -> 40 | H34: 0 | K34: =IF($E34="",0,$E34) -> 46377 | L34: =IF($F34="",0,$F34) -> 46416 | M34: =IF(OR($G34=0,$H34=""),$K34,MIN($L34+1,$K34+$G34*$H34)) -> 46377 | N34: 21 | O34: 29
A35: =IF($C35="","",ROW()-4) -> 31 | B35: 内装・設備工事 | C35: ボード貼り | D35: ☆☆内装 | E35: 46399 | F35: 46430 | G35: =IF(OR($E35="",$F35=""),0,$F35-$E35+1) -> 32 | H35: 0 | K35: =IF($E35="",0,$E35) -> 46399 | L35: =IF($F35="",0,$F35) -> 46430 | M35: =IF(OR($G35=0,$H35=""),$K35,MIN($L35+1,$K35+$G35*$H35)) -> 46399 | N35: 30
A36: =IF($C36="","",ROW()-4) -> 32 | B36: マイルストーン | C36: 受電 | E36: 46420 | F36: 46420 | G36: =IF(OR($E36="",$F36=""),0,$F36-$E36+1) -> 1 | I36: ○ | K36: =IF($E36="",0,$E36) -> 46420 | L36: =IF($F36="",0,$F36) -> 46420 | M36: =IF(OR($G36=0,$H36=""),$K36,MIN($L36+1,$K36+$G36*$H36)) -> 46420 | N36: 25
A37: =IF($C37="","",ROW()-4) -> 33 | B37: 内装・設備工事 | C37: 塗装・クロス仕上 | D37: ☆☆内装 | E37: 46426 | F37: 46451 | G37: =IF(OR($E37="",$F37=""),0,$F37-$E37+1) -> 26 | H37: 0 | K37: =IF($E37="",0,$E37) -> 46426 | L37: =IF($F37="",0,$F37) -> 46451 | M37: =IF(OR($G37=0,$H37=""),$K37,MIN($L37+1,$K37+$G37*$H37)) -> 46426 | N37: 31
A38: =IF($C38="","",ROW()-4) -> 34 | B38: 内装・設備工事 | C38: 床仕上げ | D38: ☆☆内装 | E38: 46440 | F38: 46458 | G38: =IF(OR($E38="",$F38=""),0,$F38-$E38+1) -> 19 | H38: 0 | K38: =IF($E38="",0,$E38) -> 46440 | L38: =IF($F38="",0,$F38) -> 46458 | M38: =IF(OR($G38=0,$H38=""),$K38,MIN($L38+1,$K38+$G38*$H38)) -> 46440 | N38: 33
A39: =IF($C39="","",ROW()-4) -> 35 | B39: 内装・設備工事 | C39: 照明・衛生器具取付 | D39: △△電設・◎◎設備 | E39: 46433 | F39: 46456 | G39: =IF(OR($E39="",$F39=""),0,$F39-$E39+1) -> 24 | H39: 0 | K39: =IF($E39="",0,$E39) -> 46433 | L39: =IF($F39="",0,$F39) -> 46456 | M39: =IF(OR($G39=0,$H39=""),$K39,MIN($L39+1,$K39+$G39*$H39)) -> 46433 | N39: 31 | O39: 32
A40: =IF($C40="","",ROW()-4) -> 36 | B40: 内装・設備工事 | C40: 空調機器設置・試運転調整 | D40: ◎◎設備 | E40: 46419 | F40: 46462 | G40: =IF(OR($E40="",$F40=""),0,$F40-$E40+1) -> 44 | H40: 0 | K40: =IF($E40="",0,$E40) -> 46419 | L40: =IF($F40="",0,$F40) -> 46462 | M40: =IF(OR($G40=0,$H40=""),$K40,MIN($L40+1,$K40+$G40*$H40)) -> 46419 | N40: 32
A41: =IF($C41="","",ROW()-4) -> 37 | B41: 外構工事 | C41: 外構土工・排水 | D41: ▲▲土木 | E41: 46426 | F41: 46444 | G41: =IF(OR($E41="",$F41=""),0,$F41-$E41+1) -> 19 | H41: 0 | K41: =IF($E41="",0,$E41) -> 46426 | L41: =IF($F41="",0,$F41) -> 46444 | M41: =IF(OR($G41=0,$H41=""),$K41,MIN($L41+1,$K41+$G41*$H41)) -> 46426 | N41: 28
...

Sheet 全体工程表
A1: =設定!$B$3&" 全体工程表" -> (仮称)○○ビル新築工事 全体工程表
A2: ="工期: "&TEXT(設定!$B$8,"yyyy/m/d")&" 〜 "&TEXT(設定!$B$9,"yyyy/m/d")&" 発注者: "&設定!$B$4&" 元請: "&設定!$B$5&" 現場代理人: "&設定!$B$6 -> 工期: 2026/7/1 〜 2027/3/31 発注者: ○○株式会社 元請: △△建設株式会社 現場代理人: 山田 太郎 | L2: 現在の全体進捗率: | N2: =IF(SUMPRODUCT((工程マスタ!$K$5:$K$154>0)*(工程マスタ!$I$5:$I$154<>"○")*工程マスタ!$G$5:$G$154)=0,0,SUMPRODUCT((工程マスタ!$K$5:$K$154>0)*(工程マスタ!$I$5:$I$154<>"○")*工程マスタ!$G$5:$G$154,工程マスタ!$H$5:$H$154)/SUMPRODUCT((工程マスタ!$K$5:$K$154>0)*(工程マスタ!$I$5:$I$154<>"○")*工程マスタ!$G$5:$G$154)) -> 0.044848901 | S2: =IF(SUMPRODUCT((工程マスタ!$K$5:$K$154>0)*1)>100,"※作業が100件を超えています。超過分は全体工程表に表示されません。","") | U2: 凡例: | V2: 予定 | W2: 実績 | X2: ▼ MS
H3: =設定!$B$12 -> 46204 | I3: =EDATE(H$3,1) -> 46235 | J3: =EDATE(I$3,1) -> 46266 | K3: =EDATE(J$3,1) -> 46296 | L3: =EDATE(K$3,1) -> 46327 | M3: =EDATE(L$3,1) -> 46357 | N3: =EDATE(M$3,1) -> 46388 | O3: =EDATE(N$3,1) -> 46419 | P3: =EDATE(O$3,1) -> 46447 | ... AE3: =EDATE(AD$3,1) -> 46905
H4: =IF(OR(COLUMN()=8,MONTH(H$3)=1),YEAR(H$3)&"年","") -> 2026年 | I4: =IF(OR(COLUMN()=8,MONTH(I$3)=1),YEAR(I$3)&"年","") | J4: =IF(OR(COLUMN()=8,MONTH(J$3)=1),YEAR(J$3)&"年","") | K4: =IF(OR(COLUMN()=8,MONTH(K$3)=1),YEAR(K$3)&"年","") | L4: =IF(OR(COLUMN()=8,MONTH(L$3)=1),YEAR(L$3)&"年","") | M4: =IF(OR(COLUMN()=8,MONTH(M$3)=1),YEAR(M$3)&"年","") | N4: =IF(OR(COLUMN()=8,MONTH(N$3)=1),YEAR(N$3)&"年","") -> 2027年 | O4: =IF(OR(COLUMN()=8,MONTH(O$3)=1),YEAR(O$3)&"年","") | ... AE4: =IF(OR(COLUMN()=8,MONTH(AE$3)=1),YEAR(AE$3)&"年","")
A5: No | B5: 工種 | C5: 作業名 | D5: 担当業者 | E5: 開始 | F5: 終了 | G5: 進捗 | H5: =MONTH(H$3)&"月" -> 7月 | I5: =MONTH(I$3)&"月" -> 8月 | J5: =MONTH(J$3)&"月" -> 9月 | K5: =MONTH(K$3)&"月" -> 10月 | L5: =MONTH(L$3)&"月" -> 11月 | M5: =MONTH(M$3)&"月" -> 12月 | N5: =MONTH(N$3)&"月" -> 1月 | O5: =MONTH(O$3)&"月" -> 2月 | ... AE5: =MONTH(AE$3)&"月" -> 6月
A6: =IF($AG6=0,"",IF(INDEX(工程マスタ!$A:$A,$AG6)="","",INDEX(工程マスタ!$A:$A,$AG6))) -> 1 | B6: =IF($AG6=0,"",IF(INDEX(工程マスタ!$B:$B,$AG6)="","",INDEX(工程マスタ!$B:$B,$AG6))) -> マイルストーン | C6: =IF($AG6=0,"",IF(INDEX(工程マスタ!$C:$C,$AG6)="","",INDEX(工程マスタ!$C:$C,$AG6))) -> 着工 | D6: =IF($AG6=0,"",IF(INDEX(工程マスタ!$D:$D,$AG6)="","",INDEX(工程マスタ!$D:$D,$AG6))) | E6: =IF($AG6=0,"",IF(INDEX(工程マスタ!$E:$E,$AG6)="","",INDEX(工程マスタ!$E:$E,$AG6))) -> 46204 | F6: =IF($AG6=0,"",IF(INDEX(工程マスタ!$F:$F,$AG6)="","",INDEX(工程マスタ!$F:$F,$AG6))) -> 46204 | G6: =IF($AG6=0,"",IF(INDEX(工程マスタ!$H:$H,$AG6)="","",INDEX(工程マスタ!$H:$H,$AG6))) | H6: =IF(OR($AG6=0,H$3=""),"",IF(AND(INDEX(工程マスタ!$I:$I,$AG6)="○",$E6>=H$3,$E6<EDATE(H$3,1)),"▼","")) -> ▼ | I6: =IF(OR($AG6=0,I$3=""),"",IF(AND(INDEX(工程マスタ!$I:$I,$AG6)="○",$E6>=I$3,$E6<EDATE(I$3,1)),"▼","")) | J6: =IF(OR($AG6=0,J$3=""),"",IF(AND(INDEX(工程マスタ!$I:$I,$AG6)="○",$E6>=J$3,$E6<EDATE(J$3,1)),"▼","")) | K6: =IF(OR($AG6=0,K$3=""),"",IF(AND(INDEX(工程マスタ!$I:$I,$AG6)="○",$E6>=K$3,$E6<EDATE(K$3,1)),"▼","")) | L6: =IF(OR($AG6=0,L$3=""),"",IF(AND(INDEX(工程マスタ!$I:$I,$AG6)="○",$E6>=L$3,$E6<EDATE(L$3,1)),"▼","")) | M6: =IF(OR($AG6=0,M$3=""),"",IF(AND(INDEX(工程マスタ!$I:$I,$AG6)="○",$E6>=M$3,$E6<EDATE(M$3,1)),"▼","")) | N6: =IF(OR($AG6=0,N$3=""),"",IF(AND(INDEX(工程マスタ!$I:$I,$AG6)="○",$E6>=N$3,$E6<EDATE(N$3,1)),"▼","")) | O6: =IF(OR($AG6=0,O$3=""),"",IF(AND(INDEX(工程マスタ!$I:$I,$AG6)="○",$E6>=O$3,$E6<EDATE(O$3,1)),"▼","")) | ... AE6: =IF(OR($AG6=0,AE$3=""),"",IF(AND(INDEX(工程マスタ!$I:$I,$AG6)="○",$E6>=AE$3,$E6<EDATE(AE$3,1)),"▼","")) | AG6: {=IFERROR(SMALL(IF(工程マスタ!$K$5:$K$154>0,ROW(工程マスタ!$C$5:$C$154)),1),0)} -> 5 | AH6: =IF($AG6=0,0,INDEX(工程マスタ!$M:$M,$AG6)) -> 46204
A7: =IF($AG7=0,"",IF(INDEX(工程マスタ!$A:$A,$AG7)="","",INDEX(工程マスタ!$A:$A,$AG7))) -> 2 | B7: =IF($AG7=0,"",IF(INDEX(工程マスタ!$B:$B,$AG7)="","",INDEX(工程マスタ!$B:$B,$AG7))) -> マイルストーン | C7: =IF($AG7=0,"",IF(INDEX(工程マスタ!$C:$C,$AG7)="","",INDEX(工程マスタ!$C:$C,$AG7))) -> 地鎮祭・安全祈願祭 | D7: =IF($AG7=0,"",IF(INDEX(工程マスタ!$D:$D,$AG7)="","",INDEX(工程マスタ!$D:$D,$AG7))) | E7: =IF($AG7=0,"",IF(INDEX(工程マスタ!$E:$E,$AG7)="","",INDEX(工程マスタ!$E:$E,$AG7))) -> 46207 | F7: =IF($AG7=0,"",IF(INDEX(工程マスタ!$F:$F,$AG7)="","",INDEX(工程マスタ!$F:$F,$AG7))) -> 46207 | G7: =IF($AG7=0,"",IF(INDEX(工程マスタ!$H:$H,$AG7)="","",INDEX(工程マスタ!$H:$H,$AG7))) | H7: =IF(OR($AG7=0,H$3=""),"",IF(AND(INDEX(工程マスタ!$I:$I,$AG7)="○",$E7>=H$3,$E7<EDATE(H$3,1)),"▼","")) -> ▼ | I7: =IF(OR($AG7=0,I$3=""),"",IF(AND(INDEX(工程マスタ!$I:$I,$AG7)="○",$E7>=I$3,$E7<EDATE(I$3,1)),"▼","")) | J7: =IF(OR($AG7=0,J$3=""),"",IF(AND(INDEX(工程マスタ!$I:$I,$AG7)="○",$E7>=J$3,$E7<EDATE(J$3,1)),"▼","")) | K7: =IF(OR($AG7=0,K$3=""),"",IF(AND(INDEX(工程マスタ!$I:$I,$AG7)="○",$E7>=K$3,$E7<EDATE(K$3,1)),"▼","")) | L7: =IF(OR($AG7=0,L$3=""),"",IF(AND(INDEX(工程マスタ!$I:$I,$AG7)="○",$E7>=L$3,$E7<EDATE(L$3,1)),"▼","")) | M7: =IF(OR($AG7=0,M$3=""),"",IF(AND(INDEX(工程マスタ!$I:$I,$AG7)="○",$E7>=M$3,$E7<EDATE(M$3,1)),"▼","")) | N7: =IF(OR($AG7=0,N$3=""),"",IF(AND(INDEX(工程マスタ!$I:$I,$AG7)="○",$E7>=N$3,$E7<EDATE(N$3,1)),"▼","")) | O7: =IF(OR($AG7=0,O$3=""),"",IF(AND(INDEX(工程マスタ!$I:$I,$AG7)="○",$E7>=O$3,$E7<EDATE(O$3,1)),"▼","")) | ... AE7: =IF(OR($AG7=0,AE$3=""),"",IF(AND(INDEX(工程マスタ!$I:$I,$AG7)="○",$E7>=AE$3,$E7<EDATE(AE$3,1)),"▼","")) | AG7: {=IFERROR(SMALL(IF(工程マスタ!$K$5:$K$154>0,ROW(工程マスタ!$C$5:$C$154)),2),0)} -> 6 | AH7: =IF($AG7=0,0,INDEX(工程マスタ!$M:$M,$AG7)) -> 46207
A8: =IF($AG8=0,"",IF(INDEX(工程マスタ!$A:$A,$AG8)="","",INDEX(工程マスタ!$A:$A,$AG8))) -> 3 | B8: =IF($AG8=0,"",IF(INDEX(工程マスタ!$B:$B,$AG8)="","",INDEX(工程マスタ!$B:$B,$AG8))) -> 仮設工事 | C8: =IF($AG8=0,"",IF(INDEX(工程マスタ!$C:$C,$AG8)="","",INDEX(工程マスタ!$C:$C,$AG8))) -> 仮囲い・ゲート設置 | D8: =IF($AG8=0,"",IF(INDEX(工程マスタ!$D:$D,$AG8)="","",INDEX(工程マスタ!$D:$D,$AG8))) -> ○○仮設工業 | E8: =IF($AG8=0,"",IF(INDEX(工程マスタ!$E:$E,$AG8)="","",INDEX(工程マスタ!$E:$E,$AG8))) -> 46204 | F8: =IF($AG8=0,"",IF(INDEX(工程マスタ!$F:$F,$AG8)="","",INDEX(工程マスタ!$F:$F,$AG8))) -> 46213 | G8: =IF($AG8=0,"",IF(INDEX(工程マスタ!$H:$H,$AG8)="","",INDEX(工程マスタ!$H:$H,$AG8))) -> 1 | H8: =IF(OR($AG8=0,H$3=""),"",IF(AND(INDEX(工程マスタ!$I:$I,$AG8)="○",$E8>=H$3,$E8<EDATE(H$3,1)),"▼","")) | I8: =IF(OR($AG8=0,I$3=""),"",IF(AND(INDEX(工程マスタ!$I:$I,$AG8)="○",$E8>=I$3,$E8<EDATE(I$3,1)),"▼","")) | J8: =IF(OR($AG8=0,J$3=""),"",IF(AND(INDEX(工程マスタ!$I:$I,$AG8)="○",$E8>=J$3,$E8<EDATE(J$3,1)),"▼","")) | K8: =IF(OR($AG8=0,K$3=""),"",IF(AND(INDEX(工程マスタ!$I:$I,$AG8)="○",$E8>=K$3,$E8<EDATE(K$3,1)),"▼","")) | L8: =IF(OR($AG8=0,L$3=""),"",IF(AND(INDEX(工程マスタ!$I:$I,$AG8)="○",$E8>=L$3,$E8<EDATE(L$3,1)),"▼","")) | M8: =IF(OR($AG8=0,M$3=""),"",IF(AND(INDEX(工程マスタ!$I:$I,$AG8)="○",$E8>=M$3,$E8<EDATE(M$3,1)),"▼","")) | N8: =IF(OR($AG8=0,N$3=""),"",IF(AND(INDEX(工程マスタ!$I:$I,$AG8)="○",$E8>=N$3,$E8<EDATE(N$3,1)),"▼","")) | O8: =IF(OR($AG8=0,O$3=""),"",IF(AND(INDEX(工程マスタ!$I:$I,$AG8)="○",$E8>=O$3,$E8<EDATE(O$3,1)),"▼","")) | ... AE8: =IF(OR($AG8=0,AE$3=""),"",IF(AND(INDEX(工程マスタ!$I:$I,$AG8)="○",$E8>=AE$3,$E8<EDATE(AE$3,1)),"▼","")) | AG8: {=IFERROR(SMALL(IF(工程マスタ!$K$5:$K$154>0,ROW(工程マスタ!$C$5:$C$154)),3),0)} -> 7 | AH8: =IF($AG8=0,0,INDEX(工程マスタ!$M:$M,$AG8)) -> 46214
A9: =IF($AG9=0,"",IF(INDEX(工程マスタ!$A:$A,$AG9)="","",INDEX(工程マスタ!$A:$A,$AG9))) -> 4 | B9: =IF($AG9=0,"",IF(INDEX(工程マスタ!$B:$B,$AG9)="","",INDEX(工程マスタ!$B:$B,$AG9))) -> 仮設工事 | C9: =IF($AG9=0,"",IF(INDEX(工程マスタ!$C:$C,$AG9)="","",INDEX(工程マスタ!$C:$C,$AG9))) -> 現場事務所・休憩所設置 | D9: =IF($AG9=0,"",IF(INDEX(工程マスタ!$D:$D,$AG9)="","",INDEX(工程マスタ!$D:$D,$AG9))) -> ○○仮設工業 | E9: =IF($AG9=0,"",IF(INDEX(工程マスタ!$E:$E,$AG9)="","",INDEX(工程マスタ!$E:$E,$AG9))) -> 46209 | F9: =IF($AG9=0,"",IF(INDEX(工程マスタ!$F:$F,$AG9)="","",INDEX(工程マスタ!$F:$F,$AG9))) -> 46218 | G9: =IF($AG9=0,"",IF(INDEX(工程マスタ!$H:$H,$AG9)="","",INDEX(工程マスタ!$H:$H,$AG9))) -> 1 | H9: =IF(OR($AG9=0,H$3=""),"",IF(AND(INDEX(工程マスタ!$I:$I,$AG9)="○",$E9>=H$3,$E9<EDATE(H$3,1)),"▼","")) | I9: =IF(OR($AG9=0,I$3=""),"",IF(AND(INDEX(工程マスタ!$I:$I,$AG9)="○",$E9>=I$3,$E9<EDATE(I$3,1)),"▼","")) | J9: =IF(OR($AG9=0,J$3=""),"",IF(AND(INDEX(工程マスタ!$I:$I,$AG9)="○",$E9>=J$3,$E9<EDATE(J$3,1)),"▼","")) | K9: =IF(OR($AG9=0,K$3=""),"",IF(AND(INDEX(工程マスタ!$I:$I,$AG9)="○",$E9>=K$3,$E9<EDATE(K$3,1)),"▼","")) | L9: =IF(OR($AG9=0,L$3=""),"",IF(AND(INDEX(工程マスタ!$I:$I,$AG9)="○",$E9>=L$3,$E9<EDATE(L$3,1)),"▼","")) | M9: =IF(OR($AG9=0,M$3=""),"",IF(AND(INDEX(工程マスタ!$I:$I,$AG9)="○",$E9>=M$3,$E9<EDATE(M$3,1)),"▼","")) | N9: =IF(OR($AG9=0,N$3=""),"",IF(AND(INDEX(工程マスタ!$I:$I,$AG9)="○",$E9>=N$3,$E9<EDATE(N$3,1)),"▼","")) | O9: =IF(OR($AG9=0,O$3=""),"",IF(AND(INDEX(工程マスタ!$I:$I,$AG9)="○",$E9>=O$3,$E9<EDATE(O$3,1)),"▼","")) | ... AE9: =IF(OR($AG9=0,AE$3=""),"",IF(AND(INDEX(工程マスタ!$I:$I,$AG9)="○",$E9>=AE$3,$E9<EDATE(AE$3,1)),"▼","")) | AG9: {=IFERROR(SMALL(IF(工程マスタ!$K$5:$K$154>0,ROW(工程マスタ!$C$5:$C$154)),4),0)} -> 8 | AH9: =IF($AG9=0,0,INDEX(工程マスタ!$M:$M,$AG9)) -> 46219
A10: =IF($AG10=0,"",IF(INDEX(工程マスタ!$A:$A,$AG10)="","",INDEX(工程マスタ!$A:$A,$AG10))) -> 5 | B10: =IF($AG10=0,"",IF(INDEX(工程マスタ!$B:$B,$AG10)="","",INDEX(工程マスタ!$B:$B,$AG10))) -> 仮設工事 | C10: =IF($AG10=0,"",IF(INDEX(工程マスタ!$C:$C,$AG10)="","",INDEX(工程マスタ!$C:$C,$AG10))) -> 仮設電気・給排水引込み | D10: =IF($AG10=0,"",IF(INDEX(工程マスタ!$D:$D,$AG10)="","",INDEX(工程マスタ!$D:$D,$AG10))) -> △△電設 | E10: =IF($AG10=0,"",IF(INDEX(工程マスタ!$E:$E,$AG10)="","",INDEX(工程マスタ!$E:$E,$AG10))) -> 46216 | F10: =IF($AG10=0,"",IF(INDEX(工程マスタ!$F:$F,$AG10)="","",INDEX(工程マスタ!$F:$F,$AG10))) -> 46225 | G10: =IF($AG10=0,"",IF(INDEX(工程マスタ!$H:$H,$AG10)="","",INDEX(工程マスタ!$H:$H,$AG10))) -> 0.6 | H10: =IF(OR($AG10=0,H$3=""),"",IF(AND(INDEX(工程マスタ!$I:$I,$AG10)="○",$E10>=H$3,$E10<EDATE(H$3,1)),"▼","")) | I10: =IF(OR($AG10=0,I$3=""),"",IF(AND(INDEX(工程マスタ!$I:$I,$AG10)="○",$E10>=I$3,$E10<EDATE(I$3,1)),"▼","")) | J10: =IF(OR($AG10=0,J$3=""),"",IF(AND(INDEX(工程マスタ!$I:$I,$AG10)="○",$E10>=J$3,$E10<EDATE(J$3,1)),"▼","")) | K10: =IF(OR($AG10=0,K$3=""),"",IF(AND(INDEX(工程マスタ!$I:$I,$AG10)="○",$E10>=K$3,$E10<EDATE(K$3,1)),"▼","")) | L10: =IF(OR($AG10=0,L$3=""),"",IF(AND(INDEX(工程マスタ!$I:$I,$AG10)="○",$E10>=L$3,$E10<EDATE(L$3,1)),"▼","")) | M10: =IF(OR($AG10=0,M$3=""),"",IF(AND(INDEX(工程マスタ!$I:$I,$AG10)="○",$E10>=M$3,$E10<EDATE(M$3,1)),"▼","")) | N10: =IF(OR($AG10=0,N$3=""),"",IF(AND(INDEX(工程マスタ!$I:$I,$AG10)="○",$E10>=N$3,$E10<EDATE(N$3,1)),"▼","")) | O10: =IF(OR($AG10=0,O$3=""),"",IF(AND(INDEX(工程マスタ!$I:$I,$AG10)="○",$E10>=O$3,$E10<EDATE(O$3,1)),"▼","")) | ... AE10: =IF(OR($AG10=0,AE$3=""),"",IF(AND(INDEX(工程マスタ!$I:$I,$AG10)="○",$E10>=AE$3,$E10<EDATE(AE$3,1)),"▼","")) | AG10: {=IFERROR(SMALL(IF(工程マスタ!$K$5:$K$154>0,ROW(工程マスタ!$C$5:$C$154)),5),0)} -> 9 | AH10: =IF($AG10=0,0,INDEX(工程マスタ!$M:$M,$AG10)) -> 46222
A11: =IF($AG11=0,"",IF(INDEX(工程マスタ!$A:$A,$AG11)="","",INDEX(工程マスタ!$A:$A,$AG11))) -> 6 | B11: =IF($AG11=0,"",IF(INDEX(工程マスタ!$B:$B,$AG11)="","",INDEX(工程マスタ!$B:$B,$AG11))) -> 地業基礎工事 | C11: =IF($AG11=0,"",IF(INDEX(工程マスタ!$C:$C,$AG11)="","",INDEX(工程マスタ!$C:$C,$AG11))) -> 杭工事 | D11: =IF($AG11=0,"",IF(INDEX(工程マスタ!$D:$D,$AG11)="","",INDEX(工程マスタ!$D:$D,$AG11))) -> □□基礎工業 | E11: =IF($AG11=0,"",IF(INDEX(工程マスタ!$E:$E,$AG11)="","",INDEX(工程マスタ!$E:$E,$AG11))) -> 46216 | F11: =IF($AG11=0,"",IF(INDEX(工程マスタ!$F:$F,$AG11)="","",INDEX(工程マスタ!$F:$F,$AG11))) -> 46234 | G11: =IF($AG11=0,"",IF(INDEX(工程マスタ!$H:$H,$AG11)="","",INDEX(工程マスタ!$H:$H,$AG11))) -> 0.35 | H11: =IF(OR($AG11=0,H$3=""),"",IF(AND(INDEX(工程マスタ!$I:$I,$AG11)="○",$E11>=H$3,$E11<EDATE(H$3,1)),"▼","")) | I11: =IF(OR($AG11=0,I$3=""),"",IF(AND(INDEX(工程マスタ!$I:$I,$AG11)="○",$E11>=I$3,$E11<EDATE(I$3,1)),"▼","")) | J11: =IF(OR($AG11=0,J$3=""),"",IF(AND(INDEX(工程マスタ!$I:$I,$AG11)="○",$E11>=J$3,$E11<EDATE(J$3,1)),"▼","")) | K11: =IF(OR($AG11=0,K$3=""),"",IF(AND(INDEX(工程マスタ!$I:$I,$AG11)="○",$E11>=K$3,$E11<EDATE(K$3,1)),"▼","")) | L11: =IF(OR($AG11=0,L$3=""),"",IF(AND(INDEX(工程マスタ!$I:$I,$AG11)="○",$E11>=L$3,$E11<EDATE(L$3,1)),"▼","")) | M11: =IF(OR($AG11=0,M$3=""),"",IF(AND(INDEX(工程マスタ!$I:$I,$AG11)="○",$E11>=M$3,$E11<EDATE(M$3,1)),"▼","")) | N11: =IF(OR($AG11=0,N$3=""),"",IF(AND(INDEX(工程マスタ!$I:$I,$AG11)="○",$E11>=N$3,$E11<EDATE(N$3,1)),"▼","")) | O11: =IF(OR($AG11=0,O$3=""),"",IF(AND(INDEX(工程マスタ!$I:$I,$AG11)="○",$E11>=O$3,$E11<EDATE(O$3,1)),"▼","")) | ... AE11: =IF(OR($AG11=0,AE$3=""),"",IF(AND(INDEX(工程マスタ!$I:$I,$AG11)="○",$E11>=AE$3,$E11<EDATE(AE$3,1)),"▼","")) | AG11: {=IFERROR(SMALL(IF(工程マスタ!$K$5:$K$154>0,ROW(工程マスタ!$C$5:$C$154)),6),0)} -> 10 | AH11: =IF($AG11=0,0,INDEX(工程マスタ!$M:$M,$AG11)) -> 46222.65
A12: =IF($AG12=0,"",IF(INDEX(工程マスタ!$A:$A,$AG12)="","",INDEX(工程マスタ!$A:$A,$AG12))) -> 7 | B12: =IF($AG12=0,"",IF(INDEX(工程マスタ!$B:$B,$AG12)="","",INDEX(工程マスタ!$B:$B,$AG12))) -> 土工事・山留 | C12: =IF($AG12=0,"",IF(INDEX(工程マスタ!$C:$C,$AG12)="","",INDEX(工程マスタ!$C:$C,$AG12))) -> 山留工事 | D12: =IF($AG12=0,"",IF(INDEX(工程マスタ!$D:$D,$AG12)="","",INDEX(工程マスタ!$D:$D,$AG12))) -> ▲▲土木 | E12: =IF($AG12=0,"",IF(INDEX(工程マスタ!$E:$E,$AG12)="","",INDEX(工程マスタ!$E:$E,$AG12))) -> 46230 | F12: =IF($AG12=0,"",IF(INDEX(工程マスタ!$F:$F,$AG12)="","",INDEX(工程マスタ!$F:$F,$AG12))) -> 46242 | G12: =IF($AG12=0,"",IF(INDEX(工程マスタ!$H:$H,$AG12)="","",INDEX(工程マスタ!$H:$H,$AG12))) -> 0 | H12: =IF(OR($AG12=0,H$3=""),"",IF(AND(INDEX(工程マスタ!$I:$I,$AG12)="○",$E12>=H$3,$E12<EDATE(H$3,1)),"▼","")) | I12: =IF(OR($AG12=0,I$3=""),"",IF(AND(INDEX(工程マスタ!$I:$I,$AG12)="○",$E12>=I$3,$E12<EDATE(I$3,1)),"▼","")) | J12: =IF(OR($AG12=0,J$3=""),"",IF(AND(INDEX(工程マスタ!$I:$I,$AG12)="○",$E12>=J$3,$E12<EDATE(J$3,1)),"▼","")) | K12: =IF(OR($AG12=0,K$3=""),"",IF(AND(INDEX(工程マスタ!$I:$I,$AG12)="○",$E12>=K$3,$E12<EDATE(K$3,1)),"▼","")) | L12: =IF(OR($AG12=0,L$3=""),"",IF(AND(INDEX(工程マスタ!$I:$I,$AG12)="○",$E12>=L$3,$E12<EDATE(L$3,1)),"▼","")) | M12: =IF(OR($AG12=0,M$3=""),"",IF(AND(INDEX(工程マスタ!$I:$I,$AG12)="○",$E12>=M$3,$E12<EDATE(M$3,1)),"▼","")) | N12: =IF(OR($AG12=0,N$3=""),"",IF(AND(INDEX(工程マスタ!$I:$I,$AG12)="○",$E12>=N$3,$E12<EDATE(N$3,1)),"▼","")) | O12: =IF(OR($AG12=0,O$3=""),"",IF(AND(INDEX(工程マスタ!$I:$I,$AG12)="○",$E12>=O$3,$E12<EDATE(O$3,1)),"▼","")) | ... AE12: =IF(OR($AG12=0,AE$3=""),"",IF(AND(INDEX(工程マスタ!$I:$I,$AG12)="○",$E12>=AE$3,$E12<EDATE(AE$3,1)),"▼","")) | AG12: {=IFERROR(SMALL(IF(工程マスタ!$K$5:$K$154>0,ROW(工程マスタ!$C$5:$C$154)),7),0)} -> 11 | AH12: =IF($AG12=0,0,INDEX(工程マスタ!$M:$M,$AG12)) -> 46230
A13: =IF($AG13=0,"",IF(INDEX(工程マスタ!$A:$A,$AG13)="","",INDEX(工程マスタ!$A:$A,$AG13))) -> 8 | B13: =IF($AG13=0,"",IF(INDEX(工程マスタ!$B:$B,$AG13)="","",INDEX(工程マスタ!$B:$B,$AG13))) -> 土工事・山留 | C13: =IF($AG13=0,"",IF(INDEX(工程マスタ!$C:$C,$AG13)="","",INDEX(工程マスタ!$C:$C,$AG13))) -> 根切り・掘削 | D13: =IF($AG13=0,"",IF(INDEX(工程マスタ!$D:$D,$AG13)="","",INDEX(工程マスタ!$D:$D,$AG13))) -> ▲▲土木 | E13: =IF($AG13=0,"",IF(INDEX(工程マスタ!$E:$E,$AG13)="","",INDEX(工程マスタ!$E:$E,$AG13))) -> 46237 | F13: =IF($AG13=0,"",IF(INDEX(工程マスタ!$F:$F,$AG13)="","",INDEX(工程マスタ!$F:$F,$AG13))) -> 46259 | G13: =IF($AG13=0,"",IF(INDEX(工程マスタ!$H:$H,$AG13)="","",INDEX(工程マスタ!$H:$H,$AG13))) -> 0 | H13: =IF(OR($AG13=0,H$3=""),"",IF(AND(INDEX(工程マスタ!$I:$I,$AG13)="○",$E13>=H$3,$E13<EDATE(H$3,1)),"▼","")) | I13: =IF(OR($AG13=0,I$3=""),"",IF(AND(INDEX(工程マスタ!$I:$I,$AG13)="○",$E13>=I$3,$E13<EDATE(I$3,1)),"▼","")) | J13: =IF(OR($AG13=0,J$3=""),"",IF(AND(INDEX(工程マスタ!$I:$I,$AG13)="○",$E13>=J$3,$E13<EDATE(J$3,1)),"▼","")) | K13: =IF(OR($AG13=0,K$3=""),"",IF(AND(INDEX(工程マスタ!$I:$I,$AG13)="○",$E13>=K$3,$E13<EDATE(K$3,1)),"▼","")) | L13: =IF(OR($AG13=0,L$3=""),"",IF(AND(INDEX(工程マスタ!$I:$I,$AG13)="○",$E13>=L$3,$E13<EDATE(L$3,1)),"▼","")) | M13: =IF(OR($AG13=0,M$3=""),"",IF(AND(INDEX(工程マスタ!$I:$I,$AG13)="○",$E13>=M$3,$E13<EDATE(M$3,1)),"▼","")) | N13: =IF(OR($AG13=0,N$3=""),"",IF(AND(INDEX(工程マスタ!$I:$I,$AG13)="○",$E13>=N$3,$E13<EDATE(N$3,1)),"▼","")) | O13: =IF(OR($AG13=0,O$3=""),"",IF(AND(INDEX(工程マスタ!$I:$I,$AG13)="○",$E13>=O$3,$E13<EDATE(O$3,1)),"▼","")) | ... AE13: =IF(OR($AG13=0,AE$3=""),"",IF(AND(INDEX(工程マスタ!$I:$I,$AG13)="○",$E13>=AE$3,$E13<EDATE(AE$3,1)),"▼","")) | AG13: {=IFERROR(SMALL(IF(工程マスタ!$K$5:$K$154>0,ROW(工程マスタ!$C$5:$C$154)),8),0)} -> 12 | AH13: =IF($AG13=0,0,INDEX(工程マスタ!$M:$M,$AG13)) -> 46237
A14: =IF($AG14=0,"",IF(INDEX(工程マスタ!$A:$A,$AG14)="","",INDEX(工程マスタ!$A:$A,$AG14))) -> 9 | B14: =IF($AG14=0,"",IF(INDEX(工程マスタ!$B:$B,$AG14)="","",INDEX(工程マスタ!$B:$B,$AG14))) -> 土工事・山留 | C14: =IF($AG14=0,"",IF(INDEX(工程マスタ!$C:$C,$AG14)="","",INDEX(工程マスタ!$C:$C,$AG14))) -> 床付け・捨てコンクリート | D14: =IF($AG14=0,"",IF(INDEX(工程マスタ!$D:$D,$AG14)="","",INDEX(工程マスタ!$D:$D,$AG14))) -> ▲▲土木 | E14: =IF($AG14=0,"",IF(INDEX(工程マスタ!$E:$E,$AG14)="","",INDEX(工程マスタ!$E:$E,$AG14))) -> 46258 | F14: =IF($AG14=0,"",IF(INDEX(工程マスタ!$F:$F,$AG14)="","",INDEX(工程マスタ!$F:$F,$AG14))) -> 46263 | G14: =IF($AG14=0,"",IF(INDEX(工程マスタ!$H:$H,$AG14)="","",INDEX(工程マスタ!$H:$H,$AG14))) -> 0 | H14: =IF(OR($AG14=0,H$3=""),"",IF(AND(INDEX(工程マスタ!$I:$I,$AG14)="○",$E14>=H$3,$E14<EDATE(H$3,1)),"▼","")) | I14: =IF(OR($AG14=0,I$3=""),"",IF(AND(INDEX(工程マスタ!$I:$I,$AG14)="○",$E14>=I$3,$E14<EDATE(I$3,1)),"▼","")) | J14: =IF(OR($AG14=0,J$3=""),"",IF(AND(INDEX(工程マスタ!$I:$I,$AG14)="○",$E14>=J$3,$E14<EDATE(J$3,1)),"▼","")) | K14: =IF(OR($AG14=0,K$3=""),"",IF(AND(INDEX(工程マスタ!$I:$I,$AG14)="○",$E14>=K$3,$E14<EDATE(K$3,1)),"▼","")) | L14: =IF(OR($AG14=0,L$3=""),"",IF(AND(INDEX(工程マスタ!$I:$I,$AG14)="○",$E14>=L$3,$E14<EDATE(L$3,1)),"▼","")) | M14: =IF(OR($AG14=0,M$3=""),"",IF(AND(INDEX(工程マスタ!$I:$I,$AG14)="○",$E14>=M$3,$E14<EDATE(M$3,1)),"▼","")) | N14: =IF(OR($AG14=0,N$3=""),"",IF(AND(INDEX(工程マスタ!$I:$I,$AG14)="○",$E14>=N$3,$E14<EDATE(N$3,1)),"▼","")) | O14: =IF(OR($AG14=0,O$3=""),"",IF(AND(INDEX(工程マスタ!$I:$I,$AG14)="○",$E14>=O$3,$E14<EDATE(O$3,1)),"▼","")) | ... AE14: =IF(OR($AG14=0,AE$3=""),"",IF(AND(INDEX(工程マスタ!$I:$I,$AG14)="○",$E14>=AE$3,$E14<EDATE(AE$3,1)),"▼","")) | AG14: {=IFERROR(SMALL(IF(工程マスタ!$K$5:$K$154>0,ROW(工程マスタ!$C$5:$C$154)),9),0)} -> 13 | AH14: =IF($AG14=0,0,INDEX(工程マスタ!$M:$M,$AG14)) -> 46258
A15: =IF($AG15=0,"",IF(INDEX(工程マスタ!$A:$A,$AG15)="","",INDEX(工程マスタ!$A:$A,$AG15))) -> 10 | B15: =IF($AG15=0,"",IF(INDEX(工程マスタ!$B:$B,$AG15)="","",INDEX(工程マスタ!$B:$B,$AG15))) -> 地業基礎工事 | C15: =IF($AG15=0,"",IF(INDEX(工程マスタ!$C:$C,$AG15)="","",INDEX(工程マスタ!$C:$C,$AG15))) -> 基礎配筋・型枠 | D15: =IF($AG15=0,"",IF(INDEX(工程マスタ!$D:$D,$AG15)="","",INDEX(工程マスタ!$D:$D,$AG15))) -> ◇◇建設 | E15: =IF($AG15=0,"",IF(INDEX(工程マスタ!$E:$E,$AG15)="","",INDEX(工程マスタ!$E:$E,$AG15))) -> 46265 | F15: =IF($AG15=0,"",IF(INDEX(工程マスタ!$F:$F,$AG15)="","",INDEX(工程マスタ!$F:$F,$AG15))) -> 46277 | G15: =IF($AG15=0,"",IF(INDEX(工程マスタ!$H:$H,$AG15)="","",INDEX(工程マスタ!$H:$H,$AG15))) -> 0 | H15: =IF(OR($AG15=0,H$3=""),"",IF(AND(INDEX(工程マスタ!$I:$I,$AG15)="○",$E15>=H$3,$E15<EDATE(H$3,1)),"▼","")) | I15: =IF(OR($AG15=0,I$3=""),"",IF(AND(INDEX(工程マスタ!$I:$I,$AG15)="○",$E15>=I$3,$E15<EDATE(I$3,1)),"▼","")) | J15: =IF(OR($AG15=0,J$3=""),"",IF(AND(INDEX(工程マスタ!$I:$I,$AG15)="○",$E15>=J$3,$E15<EDATE(J$3,1)),"▼","")) | K15: =IF(OR($AG15=0,K$3=""),"",IF(AND(INDEX(工程マスタ!$I:$I,$AG15)="○",$E15>=K$3,$E15<EDATE(K$3,1)),"▼","")) | L15: =IF(OR($AG15=0,L$3=""),"",IF(AND(INDEX(工程マスタ!$I:$I,$AG15)="○",$E15>=L$3,$E15<EDATE(L$3,1)),"▼","")) | M15: =IF(OR($AG15=0,M$3=""),"",IF(AND(INDEX(工程マスタ!$I:$I,$AG15)="○",$E15>=M$3,$E15<EDATE(M$3,1)),"▼","")) | N15: =IF(OR($AG15=0,N$3=""),"",IF(AND(INDEX(工程マスタ!$I:$I,$AG15)="○",$E15>=N$3,$E15<EDATE(N$3,1)),"▼","")) | O15: =IF(OR($AG15=0,O$3=""),"",IF(AND(INDEX(工程マスタ!$I:$I,$AG15)="○",$E15>=O$3,$E15<EDATE(O$3,1)),"▼","")) | ... AE15: =IF(OR($AG15=0,AE$3=""),"",IF(AND(INDEX(工程マスタ!$I:$I,$AG15)="○",$E15>=AE$3,$E15<EDATE(AE$3,1)),"▼","")) | AG15: {=IFERROR(SMALL(IF(工程マスタ!$K$5:$K$154>0,ROW(工程マスタ!$C$5:$C$154)),10),0)} -> 14 | AH15: =IF($AG15=0,0,INDEX(工程マスタ!$M:$M,$AG15)) -> 46265
A16: =IF($AG16=0,"",IF(INDEX(工程マスタ!$A:$A,$AG16)="","",INDEX(工程マスタ!$A:$A,$AG16))) -> 11 | B16: =IF($AG16=0,"",IF(INDEX(工程マスタ!$B:$B,$AG16)="","",INDEX(工程マスタ!$B:$B,$AG16))) -> 地業基礎工事 | C16: =IF($AG16=0,"",IF(INDEX(工程マスタ!$C:$C,$AG16)="","",INDEX(工程マスタ!$C:$C,$AG16))) -> 基礎コンクリート打設 | D16: =IF($AG16=0,"",IF(INDEX(工程マスタ!$D:$D,$AG16)="","",INDEX(工程マスタ!$D:$D,$AG16))) -> ◇◇建設 | E16: =IF($AG16=0,"",IF(INDEX(工程マスタ!$E:$E,$AG16)="","",INDEX(工程マスタ!$E:$E,$AG16))) -> 46279 | F16: =IF($AG16=0,"",IF(INDEX(工程マスタ!$F:$F,$AG16)="","",INDEX(工程マスタ!$F:$F,$AG16))) -> 46281 | G16: =IF($AG16=0,"",IF(INDEX(工程マスタ!$H:$H,$AG16)="","",INDEX(工程マスタ!$H:$H,$AG16))) -> 0 | H16: =IF(OR($AG16=0,H$3=""),"",IF(AND(INDEX(工程マスタ!$I:$I,$AG16)="○",$E16>=H$3,$E16<EDATE(H$3,1)),"▼","")) | I16: =IF(OR($AG16=0,I$3=""),"",IF(AND(INDEX(工程マスタ!$I:$I,$AG16)="○",$E16>=I$3,$E16<EDATE(I$3,1)),"▼","")) | J16: =IF(OR($AG16=0,J$3=""),"",IF(AND(INDEX(工程マスタ!$I:$I,$AG16)="○",$E16>=J$3,$E16<EDATE(J$3,1)),"▼","")) | K16: =IF(OR($AG16=0,K$3=""),"",IF(AND(INDEX(工程マスタ!$I:$I,$AG16)="○",$E16>=K$3,$E16<EDATE(K$3,1)),"▼","")) | L16: =IF(OR($AG16=0,L$3=""),"",IF(AND(INDEX(工程マスタ!$I:$I,$AG16)="○",$E16>=L$3,$E16<EDATE(L$3,1)),"▼","")) | M16: =IF(OR($AG16=0,M$3=""),"",IF(AND(INDEX(工程マスタ!$I:$I,$AG16)="○",$E16>=M$3,$E16<EDATE(M$3,1)),"▼","")) | N16: =IF(OR($AG16=0,N$3=""),"",IF(AND(INDEX(工程マスタ!$I:$I,$AG16)="○",$E16>=N$3,$E16<EDATE(N$3,1)),"▼","")) | O16: =IF(OR($AG16=0,O$3=""),"",IF(AND(INDEX(工程マスタ!$I:$I,$AG16)="○",$E16>=O$3,$E16<EDATE(O$3,1)),"▼","")) | ... AE16: =IF(OR($AG16=0,AE$3=""),"",IF(AND(INDEX(工程マスタ!$I:$I,$AG16)="○",$E16>=AE$3,$E16<EDATE(AE$3,1)),"▼","")) | AG16: {=IFERROR(SMALL(IF(工程マスタ!$K$5:$K$154>0,ROW(工程マスタ!$C$5:$C$154)),11),0)} -> 15 | AH16: =IF($AG16=0,0,INDEX(工程マスタ!$M:$M,$AG16)) -> 46279
A17: =IF($AG17=0,"",IF(INDEX(工程マスタ!$A:$A,$AG17)="","",INDEX(工程マスタ!$A:$A,$AG17))) -> 12 | B17: =IF($AG17=0,"",IF(INDEX(工程マスタ!$B:$B,$AG17)="","",INDEX(工程マスタ!$B:$B,$AG17))) -> 地業基礎工事 | C17: =IF($AG17=0,"",IF(INDEX(工程マスタ!$C:$C,$AG17)="","",INDEX(工程マスタ!$C:$C,$AG17))) -> 養生・埋戻し | D17: =IF($AG17=0,"",IF(INDEX(工程マスタ!$D:$D,$AG17)="","",INDEX(工程マスタ!$D:$D,$AG17))) -> ▲▲土木 | E17: =IF($AG17=0,"",IF(INDEX(工程マスタ!$E:$E,$AG17)="","",INDEX(工程マスタ!$E:$E,$AG17))) -> 46282 | F17: =IF($AG17=0,"",IF(INDEX(工程マスタ!$F:$F,$AG17)="","",INDEX(工程マスタ!$F:$F,$AG17))) -> 46291 | G17: =IF($AG17=0,"",IF(INDEX(工程マスタ!$H:$H,$AG17)="","",INDEX(工程マスタ!$H:$H,$AG17))) -> 0 | H17: =IF(OR($AG17=0,H$3=""),"",IF(AND(INDEX(工程マスタ!$I:$I,$AG17)="○",$E17>=H$3,$E17<EDATE(H$3,1)),"▼","")) | I17: =IF(OR($AG17=0,I$3=""),"",IF(AND(INDEX(工程マスタ!$I:$I,$AG17)="○",$E17>=I$3,$E17<EDATE(I$3,1)),"▼","")) | J17: =IF(OR($AG17=0,J$3=""),"",IF(AND(INDEX(工程マスタ!$I:$I,$AG17)="○",$E17>=J$3,$E17<EDATE(J$3,1)),"▼","")) | K17: =IF(OR($AG17=0,K$3=""),"",IF(AND(INDEX(工程マスタ!$I:$I,$AG17)="○",$E17>=K$3,$E17<EDATE(K$3,1)),"▼","")) | L17: =IF(OR($AG17=0,L$3=""),"",IF(AND(INDEX(工程マスタ!$I:$I,$AG17)="○",$E17>=L$3,$E17<EDATE(L$3,1)),"▼","")) | M17: =IF(OR($AG17=0,M$3=""),"",IF(AND(INDEX(工程マスタ!$I:$I,$AG17)="○",$E17>=M$3,$E17<EDATE(M$3,1)),"▼","")) | N17: =IF(OR($AG17=0,N$3=""),"",IF(AND(INDEX(工程マスタ!$I:$I,$AG17)="○",$E17>=N$3,$E17<EDATE(N$3,1)),"▼","")) | O17: =IF(OR($AG17=0,O$3=""),"",IF(AND(INDEX(工程マスタ!$I:$I,$AG17)="○",$E17>=O$3,$E17<EDATE(O$3,1)),"▼","")) | ... AE17: =IF(OR($AG17=0,AE$3=""),"",IF(AND(INDEX(工程マスタ!$I:$I,$AG17)="○",$E17>=AE$3,$E17<EDATE(AE$3,1)),"▼","")) | AG17: {=IFERROR(SMALL(IF(工程マスタ!$K$5:$K$154>0,ROW(工程マスタ!$C$5:$C$154)),12),0)} -> 16 | AH17: =IF($AG17=0,0,INDEX(工程マスタ!$M:$M,$AG17)) -> 46282
A18: =IF($AG18=0,"",IF(INDEX(工程マスタ!$A:$A,$AG18)="","",INDEX(工程マスタ!$A:$A,$AG18))) -> 13 | B18: =IF($AG18=0,"",IF(INDEX(工程マスタ!$B:$B,$AG18)="","",INDEX(工程マスタ!$B:$B,$AG18))) -> 躯体工事 | C18: =IF($AG18=0,"",IF(INDEX(工程マスタ!$C:$C,$AG18)="","",INDEX(工程マスタ!$C:$C,$AG18))) -> 鉄骨製作(工場) | D18: =IF($AG18=0,"",IF(INDEX(工程マスタ!$D:$D,$AG18)="","",INDEX(工程マスタ!$D:$D,$AG18))) -> ☆☆鉄工所 | E18: =IF($AG18=0,"",IF(INDEX(工程マスタ!$E:$E,$AG18)="","",INDEX(工程マスタ!$E:$E,$AG18))) -> 46237 | F18: =IF($AG18=0,"",IF(INDEX(工程マスタ!$F:$F,$AG18)="","",INDEX(工程マスタ!$F:$F,$AG18))) -> 46290 | G18: =IF($AG18=0,"",IF(INDEX(工程マスタ!$H:$H,$AG18)="","",INDEX(工程マスタ!$H:$H,$AG18))) -> 0 | H18: =IF(OR($AG18=0,H$3=""),"",IF(AND(INDEX(工程マスタ!$I:$I,$AG18)="○",$E18>=H$3,$E18<EDATE(H$3,1)),"▼","")) | I18: =IF(OR($AG18=0,I$3=""),"",IF(AND(INDEX(工程マスタ!$I:$I,$AG18)="○",$E18>=I$3,$E18<EDATE(I$3,1)),"▼","")) | J18: =IF(OR($AG18=0,J$3=""),"",IF(AND(INDEX(工程マスタ!$I:$I,$AG18)="○",$E18>=J$3,$E18<EDATE(J$3,1)),"▼","")) | K18: =IF(OR($AG18=0,K$3=""),"",IF(AND(INDEX(工程マスタ!$I:$I,$AG18)="○",$E18>=K$3,$E18<EDATE(K$3,1)),"▼","")) | L18: =IF(OR($AG18=0,L$3=""),"",IF(AND(INDEX(工程マスタ!$I:$I,$AG18)="○",$E18>=L$3,$E18<EDATE(L$3,1)),"▼","")) | M18: =IF(OR($AG18=0,M$3=""),"",IF(AND(INDEX(工程マスタ!$I:$I,$AG18)="○",$E18>=M$3,$E18<EDATE(M$3,1)),"▼","")) | N18: =IF(OR($AG18=0,N$3=""),"",IF(AND(INDEX(工程マスタ!$I:$I,$AG18)="○",$E18>=N$3,$E18<EDATE(N$3,1)),"▼","")) | O18: =IF(OR($AG18=0,O$3=""),"",IF(AND(INDEX(工程マスタ!$I:$I,$AG18)="○",$E18>=O$3,$E18<EDATE(O$3,1)),"▼","")) | ... AE18: =IF(OR($AG18=0,AE$3=""),"",IF(AND(INDEX(工程マスタ!$I:$I,$AG18)="○",$E18>=AE$3,$E18<EDATE(AE$3,1)),"▼","")) | AG18: {=IFERROR(SMALL(IF(工程マスタ!$K$5:$K$154>0,ROW(工程マスタ!$C$5:$C$154)),13),0)} -> 17 | AH18: =IF($AG18=0,0,INDEX(工程マスタ!$M:$M,$AG18)) -> 46237
A19: =IF($AG19=0,"",IF(INDEX(工程マスタ!$A:$A,$AG19)="","",INDEX(工程マスタ!$A:$A,$AG19))) -> 14 | B19: =IF($AG19=0,"",IF(INDEX(工程マスタ!$B:$B,$AG19)="","",INDEX(工程マスタ!$B:$B,$AG19))) -> マイルストーン | C19: =IF($AG19=0,"",IF(INDEX(工程マスタ!$C:$C,$AG19)="","",INDEX(工程マスタ!$C:$C,$AG19))) -> 鉄骨建方開始 | D19: =IF($AG19=0,"",IF(INDEX(工程マスタ!$D:$D,$AG19)="","",INDEX(工程マスタ!$D:$D,$AG19))) | E19: =IF($AG19=0,"",IF(INDEX(工程マスタ!$E:$E,$AG19)="","",INDEX(工程マスタ!$E:$E,$AG19))) -> 46293 | F19: =IF($AG19=0,"",IF(INDEX(工程マスタ!$F:$F,$AG19)="","",INDEX(工程マスタ!$F:$F,$AG19))) -> 46293 | G19: =IF($AG19=0,"",IF(INDEX(工程マスタ!$H:$H,$AG19)="","",INDEX(工程マスタ!$H:$H,$AG19))) | H19: =IF(OR($AG19=0,H$3=""),"",IF(AND(INDEX(工程マスタ!$I:$I,$AG19)="○",$E19>=H$3,$E19<EDATE(H$3,1)),"▼","")) | I19: =IF(OR($AG19=0,I$3=""),"",IF(AND(INDEX(工程マスタ!$I:$I,$AG19)="○",$E19>=I$3,$E19<EDATE(I$3,1)),"▼","")) | J19: =IF(OR($AG19=0,J$3=""),"",IF(AND(INDEX(工程マスタ!$I:$I,$AG19)="○",$E19>=J$3,$E19<EDATE(J$3,1)),"▼","")) -> ▼ | K19: =IF(OR($AG19=0,K$3=""),"",IF(AND(INDEX(工程マスタ!$I:$I,$AG19)="○",$E19>=K$3,$E19<EDATE(K$3,1)),"▼","")) | L19: =IF(OR($AG19=0,L$3=""),"",IF(AND(INDEX(工程マスタ!$I:$I,$AG19)="○",$E19>=L$3,$E19<EDATE(L$3,1)),"▼","")) | M19: =IF(OR($AG19=0,M$3=""),"",IF(AND(INDEX(工程マスタ!$I:$I,$AG19)="○",$E19>=M$3,$E19<EDATE(M$3,1)),"▼","")) | N19: =IF(OR($AG19=0,N$3=""),"",IF(AND(INDEX(工程マスタ!$I:$I,$AG19)="○",$E19>=N$3,$E19<EDATE(N$3,1)),"▼","")) | O19: =IF(OR($AG19=0,O$3=""),"",IF(AND(INDEX(工程マスタ!$I:$I,$AG19)="○",$E19>=O$3,$E19<EDATE(O$3,1)),"▼","")) | ... AE19: =IF(OR($AG19=0,AE$3=""),"",IF(AND(INDEX(工程マスタ!$I:$I,$AG19)="○",$E19>=AE$3,$E19<EDATE(AE$3,1)),"▼","")) | AG19: {=IFERROR(SMALL(IF(工程マスタ!$K$5:$K$154>0,ROW(工程マスタ!$C$5:$C$154)),14),0)} -> 18 | AH19: =IF($AG19=0,0,INDEX(工程マスタ!$M:$M,$AG19)) -> 46293
A20: =IF($AG20=0,"",IF(INDEX(工程マスタ!$A:$A,$AG20)="","",INDEX(工程マスタ!$A:$A,$AG20))) -> 15 | B20: =IF($AG20=0,"",IF(INDEX(工程マスタ!$B:$B,$AG20)="","",INDEX(工程マスタ!$B:$B,$AG20))) -> 仮設工事 | C20: =IF($AG20=0,"",IF(INDEX(工程マスタ!$C:$C,$AG20)="","",INDEX(工程マスタ!$C:$C,$AG20))) -> 外部足場組立 | D20: =IF($AG20=0,"",IF(INDEX(工程マスタ!$D:$D,$AG20)="","",INDEX(工程マスタ!$D:$D,$AG20))) -> ○○仮設工業 | E20: =IF($AG20=0,"",IF(INDEX(工程マスタ!$E:$E,$AG20)="","",INDEX(工程マスタ!$E:$E,$AG20))) -> 46289 | F20: =IF($AG20=0,"",IF(INDEX(工程マスタ!$F:$F,$AG20)="","",INDEX(工程マスタ!$F:$F,$AG20))) -> 46301 | G20: =IF($AG20=0,"",IF(INDEX(工程マスタ!$H:$H,$AG20)="","",INDEX(工程マスタ!$H:$H,$AG20))) -> 0 | H20: =IF(OR($AG20=0,H$3=""),"",IF(AND(INDEX(工程マスタ!$I:$I,$AG20)="○",$E20>=H$3,$E20<EDATE(H$3,1)),"▼","")) | I20: =IF(OR($AG20=0,I$3=""),"",IF(AND(INDEX(工程マスタ!$I:$I,$AG20)="○",$E20>=I$3,$E20<EDATE(I$3,1)),"▼","")) | J20: =IF(OR($AG20=0,J$3=""),"",IF(AND(INDEX(工程マスタ!$I:$I,$AG20)="○",$E20>=J$3,$E20<EDATE(J$3,1)),"▼","")) | K20: =IF(OR($AG20=0,K$3=""),"",IF(AND(INDEX(工程マスタ!$I:$I,$AG20)="○",$E20>=K$3,$E20<EDATE(K$3,1)),"▼","")) | L20: =IF(OR($AG20=0,L$3=""),"",IF(AND(INDEX(工程マスタ!$I:$I,$AG20)="○",$E20>=L$3,$E20<EDATE(L$3,1)),"▼","")) | M20: =IF(OR($AG20=0,M$3=""),"",IF(AND(INDEX(工程マスタ!$I:$I,$AG20)="○",$E20>=M$3,$E20<EDATE(M$3,1)),"▼","")) | N20: =IF(OR($AG20=0,N$3=""),"",IF(AND(INDEX(工程マスタ!$I:$I,$AG20)="○",$E20>=N$3,$E20<EDATE(N$3,1)),"▼","")) | O20: =IF(OR($AG20=0,O$3=""),"",IF(AND(INDEX(工程マスタ!$I:$I,$AG20)="○",$E20>=O$3,$E20<EDATE(O$3,1)),"▼","")) | ... AE20: =IF(OR($AG20=0,AE$3=""),"",IF(AND(INDEX(工程マスタ!$I:$I,$AG20)="○",$E20>=AE$3,$E20<EDATE(AE$3,1)),"▼","")) | AG20: {=IFERROR(SMALL(IF(工程マスタ!$K$5:$K$154>0,ROW(工程マスタ!$C$5:$C$154)),15),0)} -> 19 | AH20: =IF($AG20=0,0,INDEX(工程マスタ!$M:$M,$AG20)) -> 46289
A21: =IF($AG21=0,"",IF(INDEX(工程マスタ!$A:$A,$AG21)="","",INDEX(工程マスタ!$A:$A,$AG21))) -> 16 | B21: =IF($AG21=0,"",IF(INDEX(工程マスタ!$B:$B,$AG21)="","",INDEX(工程マスタ!$B:$B,$AG21))) -> 躯体工事 | C21: =IF($AG21=0,"",IF(INDEX(工程マスタ!$C:$C,$AG21)="","",INDEX(工程マスタ!$C:$C,$AG21))) -> 鉄骨建方 | D21: =IF($AG21=0,"",IF(INDEX(工程マスタ!$D:$D,$AG21)="","",INDEX(工程マスタ!$D:$D,$AG21))) -> ☆☆鉄工所 | E21: =IF($AG21=0,"",IF(INDEX(工程マスタ!$E:$E,$AG21)="","",INDEX(工程マスタ!$E:$E,$AG21))) -> 46293 | F21: =IF($AG21=0,"",IF(INDEX(工程マスタ!$F:$F,$AG21)="","",INDEX(工程マスタ!$F:$F,$AG21))) -> 46318 | G21: =IF($AG21=0,"",IF(INDEX(工程マスタ!$H:$H,$AG21)="","",INDEX(工程マスタ!$H:$H,$AG21))) -> 0 | H21: =IF(OR($AG21=0,H$3=""),"",IF(AND(INDEX(工程マスタ!$I:$I,$AG21)="○",$E21>=H$3,$E21<EDATE(H$3,1)),"▼","")) | I21: =IF(OR($AG21=0,I$3=""),"",IF(AND(INDEX(工程マスタ!$I:$I,$AG21)="○",$E21>=I$3,$E21<EDATE(I$3,1)),"▼","")) | J21: =IF(OR($AG21=0,J$3=""),"",IF(AND(INDEX(工程マスタ!$I:$I,$AG21)="○",$E21>=J$3,$E21<EDATE(J$3,1)),"▼","")) | K21: =IF(OR($AG21=0,K$3=""),"",IF(AND(INDEX(工程マスタ!$I:$I,$AG21)="○",$E21>=K$3,$E21<EDATE(K$3,1)),"▼","")) | L21: =IF(OR($AG21=0,L$3=""),"",IF(AND(INDEX(工程マスタ!$I:$I,$AG21)="○",$E21>=L$3,$E21<EDATE(L$3,1)),"▼","")) | M21: =IF(OR($AG21=0,M$3=""),"",IF(AND(INDEX(工程マスタ!$I:$I,$AG21)="○",$E21>=M$3,$E21<EDATE(M$3,1)),"▼","")) | N21: =IF(OR($AG21=0,N$3=""),"",IF(AND(INDEX(工程マスタ!$I:$I,$AG21)="○",$E21>=N$3,$E21<EDATE(N$3,1)),"▼","")) | O21: =IF(OR($AG21=0,O$3=""),"",IF(AND(INDEX(工程マスタ!$I:$I,$AG21)="○",$E21>=O$3,$E21<EDATE(O$3,1)),"▼","")) | ... AE21: =IF(OR($AG21=0,AE$3=""),"",IF(AND(INDEX(工程マスタ!$I:$I,$AG21)="○",$E21>=AE$3,$E21<EDATE(AE$3,1)),"▼","")) | AG21: {=IFERROR(SMALL(IF(工程マスタ!$K$5:$K$154>0,ROW(工程マスタ!$C$5:$C$154)),16),0)} -> 20 | AH21: =IF($AG21=0,0,INDEX(工程マスタ!$M:$M,$AG21)) -> 46293
A22: =IF($AG22=0,"",IF(INDEX(工程マスタ!$A:$A,$AG22)="","",INDEX(工程マスタ!$A:$A,$AG22))) -> 17 | B22: =IF($AG22=0,"",IF(INDEX(工程マスタ!$B:$B,$AG22)="","",INDEX(工程マスタ!$B:$B,$AG22))) -> マイルストーン | C22: =IF($AG22=0,"",IF(INDEX(工程マスタ!$C:$C,$AG22)="","",INDEX(工程マスタ!$C:$C,$AG22))) -> 上棟 | D22: =IF($AG22=0,"",IF(INDEX(工程マスタ!$D:$D,$AG22)="","",INDEX(工程マスタ!$D:$D,$AG22))) | E22: =IF($AG22=0,"",IF(INDEX(工程マスタ!$E:$E,$AG22)="","",INDEX(工程マスタ!$E:$E,$AG22))) -> 46318 | F22: =IF($AG22=0,"",IF(INDEX(工程マスタ!$F:$F,$AG22)="","",INDEX(工程マスタ!$F:$F,$AG22))) -> 46318 | G22: =IF($AG22=0,"",IF(INDEX(工程マスタ!$H:$H,$AG22)="","",INDEX(工程マスタ!$H:$H,$AG22))) | H22: =IF(OR($AG22=0,H$3=""),"",IF(AND(INDEX(工程マスタ!$I:$I,$AG22)="○",$E22>=H$3,$E22<EDATE(H$3,1)),"▼","")) | I22: =IF(OR($AG22=0,I$3=""),"",IF(AND(INDEX(工程マスタ!$I:$I,$AG22)="○",$E22>=I$3,$E22<EDATE(I$3,1)),"▼","")) | J22: =IF(OR($AG22=0,J$3=""),"",IF(AND(INDEX(工程マスタ!$I:$I,$AG22)="○",$E22>=J$3,$E22<EDATE(J$3,1)),"▼","")) | K22: =IF(OR($AG22=0,K$3=""),"",IF(AND(INDEX(工程マスタ!$I:$I,$AG22)="○",$E22>=K$3,$E22<EDATE(K$3,1)),"▼","")) -> ▼ | L22: =IF(OR($AG22=0,L$3=""),"",IF(AND(INDEX(工程マスタ!$I:$I,$AG22)="○",$E22>=L$3,$E22<EDATE(L$3,1)),"▼","")) | M22: =IF(OR($AG22=0,M$3=""),"",IF(AND(INDEX(工程マスタ!$I:$I,$AG22)="○",$E22>=M$3,$E22<EDATE(M$3,1)),"▼","")) | N22: =IF(OR($AG22=0,N$3=""),"",IF(AND(INDEX(工程マスタ!$I:$I,$AG22)="○",$E22>=N$3,$E22<EDATE(N$3,1)),"▼","")) | O22: =IF(OR($AG22=0,O$3=""),"",IF(AND(INDEX(工程マスタ!$I:$I,$AG22)="○",$E22>=O$3,$E22<EDATE(O$3,1)),"▼","")) | ... AE22: =IF(OR($AG22=0,AE$3=""),"",IF(AND(INDEX(工程マスタ!$I:$I,$AG22)="○",$E22>=AE$3,$E22<EDATE(AE$3,1)),"▼","")) | AG22: {=IFERROR(SMALL(IF(工程マスタ!$K$5:$K$154>0,ROW(工程マスタ!$C$5:$C$154)),17),0)} -> 21 | AH22: =IF($AG22=0,0,INDEX(工程マスタ!$M:$M,$AG22)) -> 46318
A23: =IF($AG23=0,"",IF(INDEX(工程マスタ!$A:$A,$AG23)="","",INDEX(工程マスタ!$A:$A,$AG23))) -> 18 | B23: =IF($AG23=0,"",IF(INDEX(工程マスタ!$B:$B,$AG23)="","",INDEX(工程マスタ!$B:$B,$AG23))) -> 躯体工事 | C23: =IF($AG23=0,"",IF(INDEX(工程マスタ!$C:$C,$AG23)="","",INDEX(工程マスタ!$C:$C,$AG23))) -> 本締め・建入れ検査 | D23: =IF($AG23=0,"",IF(INDEX(工程マスタ!$D:$D,$AG23)="","",INDEX(工程マスタ!$D:$D,$AG23))) -> ☆☆鉄工所 | E23: =IF($AG23=0,"",IF(INDEX(工程マスタ!$E:$E,$AG23)="","",INDEX(工程マスタ!$E:$E,$AG23))) -> 46321 | F23: =IF($AG23=0,"",IF(INDEX(工程マスタ!$F:$F,$AG23)="","",INDEX(工程マスタ!$F:$F,$AG23))) -> 46332 | G23: =IF($AG23=0,"",IF(INDEX(工程マスタ!$H:$H,$AG23)="","",INDEX(工程マスタ!$H:$H,$AG23))) -> 0 | H23: =IF(OR($AG23=0,H$3=""),"",IF(AND(INDEX(工程マスタ!$I:$I,$AG23)="○",$E23>=H$3,$E23<EDATE(H$3,1)),"▼","")) | I23: =IF(OR($AG23=0,I$3=""),"",IF(AND(INDEX(工程マスタ!$I:$I,$AG23)="○",$E23>=I$3,$E23<EDATE(I$3,1)),"▼","")) | J23: =IF(OR($AG23=0,J$3=""),"",IF(AND(INDEX(工程マスタ!$I:$I,$AG23)="○",$E23>=J$3,$E23<EDATE(J$3,1)),"▼","")) | K23: =IF(OR($AG23=0,K$3=""),"",IF(AND(INDEX(工程マスタ!$I:$I,$AG23)="○",$E23>=K$3,$E23<EDATE(K$3,1)),"▼","")) | L23: =IF(OR($AG23=0,L$3=""),"",IF(AND(INDEX(工程マスタ!$I:$I,$AG23)="○",$E23>=L$3,$E23<EDATE(L$3,1)),"▼","")) | M23: =IF(OR($AG23=0,M$3=""),"",IF(AND(INDEX(工程マスタ!$I:$I,$AG23)="○",$E23>=M$3,$E23<EDATE(M$3,1)),"▼","")) | N23: =IF(OR($AG23=0,N$3=""),"",IF(AND(INDEX(工程マスタ!$I:$I,$AG23)="○",$E23>=N$3,$E23<EDATE(N$3,1)),"▼","")) | O23: =IF(OR($AG23=0,O$3=""),"",IF(AND(INDEX(工程マスタ!$I:$I,$AG23)="○",$E23>=O$3,$E23<EDATE(O$3,1)),"▼","")) | ... AE23: =IF(OR($AG23=0,AE$3=""),"",IF(AND(INDEX(工程マスタ!$I:$I,$AG23)="○",$E23>=AE$3,$E23<EDATE(AE$3,1)),"▼","")) | AG23: {=IFERROR(SMALL(IF(工程マスタ!$K$5:$K$154>0,ROW(工程マスタ!$C$5:$C$154)),18),0)} -> 22 | AH23: =IF($AG23=0,0,INDEX(工程マスタ!$M:$M,$AG23)) -> 46321
A24: =IF($AG24=0,"",IF(INDEX(工程マスタ!$A:$A,$AG24)="","",INDEX(工程マスタ!$A:$A,$AG24))) -> 19 | B24: =IF($AG24=0,"",IF(INDEX(工程マスタ!$B:$B,$AG24)="","",INDEX(工程マスタ!$B:$B,$AG24))) -> 躯体工事 | C24: =IF($AG24=0,"",IF(INDEX(工程マスタ!$C:$C,$AG24)="","",INDEX(工程マスタ!$C:$C,$AG24))) -> デッキ・スタッド溶接 | D24: =IF($AG24=0,"",IF(INDEX(工程マスタ!$D:$D,$AG24)="","",INDEX(工程マスタ!$D:$D,$AG24))) -> ☆☆鉄工所 | E24: =IF($AG24=0,"",IF(INDEX(工程マスタ!$E:$E,$AG24)="","",INDEX(工程マスタ!$E:$E,$AG24))) -> 46314 | F24: =IF($AG24=0,"",IF(INDEX(工程マスタ!$F:$F,$AG24)="","",INDEX(工程マスタ!$F:$F,$AG24))) -> 46339 | G24: =IF($AG24=0,"",IF(INDEX(工程マスタ!$H:$H,$AG24)="","",INDEX(工程マスタ!$H:$H,$AG24))) -> 0 | H24: =IF(OR($AG24=0,H$3=""),"",IF(AND(INDEX(工程マスタ!$I:$I,$AG24)="○",$E24>=H$3,$E24<EDATE(H$3,1)),"▼","")) | I24: =IF(OR($AG24=0,I$3=""),"",IF(AND(INDEX(工程マスタ!$I:$I,$AG24)="○",$E24>=I$3,$E24<EDATE(I$3,1)),"▼","")) | J24: =IF(OR($AG24=0,J$3=""),"",IF(AND(INDEX(工程マスタ!$I:$I,$AG24)="○",$E24>=J$3,$E24<EDATE(J$3,1)),"▼","")) | K24: =IF(OR($AG24=0,K$3=""),"",IF(AND(INDEX(工程マスタ!$I:$I,$AG24)="○",$E24>=K$3,$E24<EDATE(K$3,1)),"▼","")) | L24: =IF(OR($AG24=0,L$3=""),"",IF(AND(INDEX(工程マスタ!$I:$I,$AG24)="○",$E24>=L$3,$E24<EDATE(L$3,1)),"▼","")) | M24: =IF(OR($AG24=0,M$3=""),"",IF(AND(INDEX(工程マスタ!$I:$I,$AG24)="○",$E24>=M$3,$E24<EDATE(M$3,1)),"▼","")) | N24: =IF(OR($AG24=0,N$3=""),"",IF(AND(INDEX(工程マスタ!$I:$I,$AG24)="○",$E24>=N$3,$E24<EDATE(N$3,1)),"▼","")) | O24: =IF(OR($AG24=0,O$3=""),"",IF(AND(INDEX(工程マスタ!$I:$I,$AG24)="○",$E24>=O$3,$E24<EDATE(O$3,1)),"▼","")) | ... AE24: =IF(OR($AG24=0,AE$3=""),"",IF(AND(INDEX(工程マスタ!$I:$I,$AG24)="○",$E24>=AE$3,$E24<EDATE(AE$3,1)),"▼","")) | AG24: {=IFERROR(SMALL(IF(工程マスタ!$K$5:$K$154>0,ROW(工程マスタ!$C$5:$C$154)),19),0)} -> 23 | AH24: =IF($AG24=0,0,INDEX(工程マスタ!$M:$M,$AG24)) -> 46314
A25: =IF($AG25=0,"",IF(INDEX(工程マスタ!$A:$A,$AG25)="","",INDEX(工程マスタ!$A:$A,$AG25))) -> 20 | B25: =IF($AG25=0,"",IF(INDEX(工程マスタ!$B:$B,$AG25)="","",INDEX(工程マスタ!$B:$B,$AG25))) -> 躯体工事 | C25: =IF($AG25=0,"",IF(INDEX(工程マスタ!$C:$C,$AG25)="","",INDEX(工程マスタ!$C:$C,$AG25))) -> 床コンクリート打設 | D25: =IF($AG25=0,"",IF(INDEX(工程マスタ!$D:$D,$AG25)="","",INDEX(工程マスタ!$D:$D,$AG25))) -> ◇◇建設 | E25: =IF($AG25=0,"",IF(INDEX(工程マスタ!$E:$E,$AG25)="","",INDEX(工程マスタ!$E:$E,$AG25))) -> 46335 | F25: =IF($AG25=0,"",IF(INDEX(工程マスタ!$F:$F,$AG25)="","",INDEX(工程マスタ!$F:$F,$AG25))) -> 46353 | G25: =IF($AG25=0,"",IF(INDEX(工程マスタ!$H:$H,$AG25)="","",INDEX(工程マスタ!$H:$H,$AG25))) -> 0 | H25: =IF(OR($AG25=0,H$3=""),"",IF(AND(INDEX(工程マスタ!$I:$I,$AG25)="○",$E25>=H$3,$E25<EDATE(H$3,1)),"▼","")) | I25: =IF(OR($AG25=0,I$3=""),"",IF(AND(INDEX(工程マスタ!$I:$I,$AG25)="○",$E25>=I$3,$E25<EDATE(I$3,1)),"▼","")) | J25: =IF(OR($AG25=0,J$3=""),"",IF(AND(INDEX(工程マスタ!$I:$I,$AG25)="○",$E25>=J$3,$E25<EDATE(J$3,1)),"▼","")) | K25: =IF(OR($AG25=0,K$3=""),"",IF(AND(INDEX(工程マスタ!$I:$I,$AG25)="○",$E25>=K$3,$E25<EDATE(K$3,1)),"▼","")) | L25: =IF(OR($AG25=0,L$3=""),"",IF(AND(INDEX(工程マスタ!$I:$I,$AG25)="○",$E25>=L$3,$E25<EDATE(L$3,1)),"▼","")) | M25: =IF(OR($AG25=0,M$3=""),"",IF(AND(INDEX(工程マスタ!$I:$I,$AG25)="○",$E25>=M$3,$E25<EDATE(M$3,1)),"▼","")) | N25: =IF(OR($AG25=0,N$3=""),"",IF(AND(INDEX(工程マスタ!$I:$I,$AG25)="○",$E25>=N$3,$E25<EDATE(N$3,1)),"▼","")) | O25: =IF(OR($AG25=0,O$3=""),"",IF(AND(INDEX(工程マスタ!$I:$I,$AG25)="○",$E25>=O$3,$E25<EDATE(O$3,1)),"▼","")) | ... AE25: =IF(OR($AG25=0,AE$3=""),"",IF(AND(INDEX(工程マスタ!$I:$I,$AG25)="○",$E25>=AE$3,$E25<EDATE(AE$3,1)),"▼","")) | AG25: {=IFERROR(SMALL(IF(工程マスタ!$K$5:$K$154>0,ROW(工程マスタ!$C$5:$C$154)),20),0)} -> 24 | AH25: =IF($AG25=0,0,INDEX(工程マスタ!$M:$M,$AG25)) -> 46335
A26: =IF($AG26=0,"",IF(INDEX(工程マスタ!$A:$A,$AG26)="","",INDEX(工程マスタ!$A:$A,$AG26))) -> 21 | B26: =IF($AG26=0,"",IF(INDEX(工程マスタ!$B:$B,$AG26)="","",INDEX(工程マスタ!$B:$B,$AG26))) -> 外装工事 | C26: =IF($AG26=0,"",IF(INDEX(工程マスタ!$C:$C,$AG26)="","",INDEX(工程マスタ!$C:$C,$AG26))) -> 屋根・屋上防水 | D26: =IF($AG26=0,"",IF(INDEX(工程マスタ!$D:$D,$AG26)="","",INDEX(工程マスタ!$D:$D,$AG26))) -> ●●防水 | E26: =IF($AG26=0,"",IF(INDEX(工程マスタ!$E:$E,$AG26)="","",INDEX(工程マスタ!$E:$E,$AG26))) -> 46350 | F26: =IF($AG26=0,"",IF(INDEX(工程マスタ!$F:$F,$AG26)="","",INDEX(工程マスタ!$F:$F,$AG26))) -> 46374 | G26: =IF($AG26=0,"",IF(INDEX(工程マスタ!$H:$H,$AG26)="","",INDEX(工程マスタ!$H:$H,$AG26))) -> 0 | H26: =IF(OR($AG26=0,H$3=""),"",IF(AND(INDEX(工程マスタ!$I:$I,$AG26)="○",$E26>=H$3,$E26<EDATE(H$3,1)),"▼","")) | I26: =IF(OR($AG26=0,I$3=""),"",IF(AND(INDEX(工程マスタ!$I:$I,$AG26)="○",$E26>=I$3,$E26<EDATE(I$3,1)),"▼","")) | J26: =IF(OR($AG26=0,J$3=""),"",IF(AND(INDEX(工程マスタ!$I:$I,$AG26)="○",$E26>=J$3,$E26<EDATE(J$3,1)),"▼","")) | K26: =IF(OR($AG26=0,K$3=""),"",IF(AND(INDEX(工程マスタ!$I:$I,$AG26)="○",$E26>=K$3,$E26<EDATE(K$3,1)),"▼","")) | L26: =IF(OR($AG26=0,L$3=""),"",IF(AND(INDEX(工程マスタ!$I:$I,$AG26)="○",$E26>=L$3,$E26<EDATE(L$3,1)),"▼","")) | M26: =IF(OR($AG26=0,M$3=""),"",IF(AND(INDEX(工程マスタ!$I:$I,$AG26)="○",$E26>=M$3,$E26<EDATE(M$3,1)),"▼","")) | N26: =IF(OR($AG26=0,N$3=""),"",IF(AND(INDEX(工程マスタ!$I:$I,$AG26)="○",$E26>=N$3,$E26<EDATE(N$3,1)),"▼","")) | O26: =IF(OR($AG26=0,O$3=""),"",IF(AND(INDEX(工程マスタ!$I:$I,$AG26)="○",$E26>=O$3,$E26<EDATE(O$3,1)),"▼","")) | ... AE26: =IF(OR($AG26=0,AE$3=""),"",IF(AND(INDEX(工程マスタ!$I:$I,$AG26)="○",$E26>=AE$3,$E26<EDATE(AE$3,1)),"▼","")) | AG26: {=IFERROR(SMALL(IF(工程マスタ!$K$5:$K$154>0,ROW(工程マスタ!$C$5:$C$154)),21),0)} -> 25 | AH26: =IF($AG26=0,0,INDEX(工程マスタ!$M:$M,$AG26)) -> 46350
A27: =IF($AG27=0,"",IF(INDEX(工程マスタ!$A:$A,$AG27)="","",INDEX(工程マスタ!$A:$A,$AG27))) -> 22 | B27: =IF($AG27=0,"",IF(INDEX(工程マスタ!$B:$B,$AG27)="","",INDEX(工程マスタ!$B:$B,$AG27))) -> 外装工事 | C27: =IF($AG27=0,"",IF(INDEX(工程マスタ!$C:$C,$AG27)="","",INDEX(工程マスタ!$C:$C,$AG27))) -> 外壁下地・胴縁 | D27: =IF($AG27=0,"",IF(INDEX(工程マスタ!$D:$D,$AG27)="","",INDEX(工程マスタ!$D:$D,$AG27))) -> ■■外装 | E27: =IF($AG27=0,"",IF(INDEX(工程マスタ!$E:$E,$AG27)="","",INDEX(工程マスタ!$E:$E,$AG27))) -> 46342 | F27: =IF($AG27=0,"",IF(INDEX(工程マスタ!$F:$F,$AG27)="","",INDEX(工程マスタ!$F:$F,$AG27))) -> 46360 | G27: =IF($AG27=0,"",IF(INDEX(工程マスタ!$H:$H,$AG27)="","",INDEX(工程マスタ!$H:$H,$AG27))) -> 0 | H27: =IF(OR($AG27=0,H$3=""),"",IF(AND(INDEX(工程マスタ!$I:$I,$AG27)="○",$E27>=H$3,$E27<EDATE(H$3,1)),"▼","")) | I27: =IF(OR($AG27=0,I$3=""),"",IF(AND(INDEX(工程マスタ!$I:$I,$AG27)="○",$E27>=I$3,$E27<EDATE(I$3,1)),"▼","")) | J27: =IF(OR($AG27=0,J$3=""),"",IF(AND(INDEX(工程マスタ!$I:$I,$AG27)="○",$E27>=J$3,$E27<EDATE(J$3,1)),"▼","")) | K27: =IF(OR($AG27=0,K$3=""),"",IF(AND(INDEX(工程マスタ!$I:$I,$AG27)="○",$E27>=K$3,$E27<EDATE(K$3,1)),"▼","")) | L27: =IF(OR($AG27=0,L$3=""),"",IF(AND(INDEX(工程マスタ!$I:$I,$AG27)="○",$E27>=L$3,$E27<EDATE(L$3,1)),"▼","")) | M27: =IF(OR($AG27=0,M$3=""),"",IF(AND(INDEX(工程マスタ!$I:$I,$AG27)="○",$E27>=M$3,$E27<EDATE(M$3,1)),"▼","")) | N27: =IF(OR($AG27=0,N$3=""),"",IF(AND(INDEX(工程マスタ!$I:$I,$AG27)="○",$E27>=N$3,$E27<EDATE(N$3,1)),"▼","")) | O27: =IF(OR($AG27=0,O$3=""),"",IF(AND(INDEX(工程マスタ!$I:$I,$AG27)="○",$E27>=O$3,$E27<EDATE(O$3,1)),"▼","")) | ... AE27: =IF(OR($AG27=0,AE$3=""),"",IF(AND(INDEX(工程マスタ!$I:$I,$AG27)="○",$E27>=AE$3,$E27<EDATE(AE$3,1)),"▼","")) | AG27: {=IFERROR(SMALL(IF(工程マスタ!$K$5:$K$154>0,ROW(工程マスタ!$C$5:$C$154)),22),0)} -> 26 | AH27: =IF($AG27=0,0,INDEX(工程マスタ!$M:$M,$AG27)) -> 46342
A28: =IF($AG28=0,"",IF(INDEX(工程マスタ!$A:$A,$AG28)="","",INDEX(工程マスタ!$A:$A,$AG28))) -> 23 | B28: =IF($AG28=0,"",IF(INDEX(工程マスタ!$B:$B,$AG28)="","",INDEX(工程マスタ!$B:$B,$AG28))) -> 外装工事 | C28: =IF($AG28=0,"",IF(INDEX(工程マスタ!$C:$C,$AG28)="","",INDEX(工程マスタ!$C:$C,$AG28))) -> 外壁パネル(ALC)取付 | D28: =IF($AG28=0,"",IF(INDEX(工程マスタ!$D:$D,$AG28)="","",INDEX(工程マスタ!$D:$D,$AG28))) -> ■■外装 | E28: =IF($AG28=0,"",IF(INDEX(工程マスタ!$E:$E,$AG28)="","",INDEX(工程マスタ!$E:$E,$AG28))) -> 46356 | F28: =IF($AG28=0,"",IF(INDEX(工程マスタ!$F:$F,$AG28)="","",INDEX(工程マスタ!$F:$F,$AG28))) -> 46381 | G28: =IF($AG28=0,"",IF(INDEX(工程マスタ!$H:$H,$AG28)="","",INDEX(工程マスタ!$H:$H,$AG28))) -> 0 | H28: =IF(OR($AG28=0,H$3=""),"",IF(AND(INDEX(工程マスタ!$I:$I,$AG28)="○",$E28>=H$3,$E28<EDATE(H$3,1)),"▼","")) | I28: =IF(OR($AG28=0,I$3=""),"",IF(AND(INDEX(工程マスタ!$I:$I,$AG28)="○",$E28>=I$3,$E28<EDATE(I$3,1)),"▼","")) | J28: =IF(OR($AG28=0,J$3=""),"",IF(AND(INDEX(工程マスタ!$I:$I,$AG28)="○",$E28>=J$3,$E28<EDATE(J$3,1)),"▼","")) | K28: =IF(OR($AG28=0,K$3=""),"",IF(AND(INDEX(工程マスタ!$I:$I,$AG28)="○",$E28>=K$3,$E28<EDATE(K$3,1)),"▼","")) | L28: =IF(OR($AG28=0,L$3=""),"",IF(AND(INDEX(工程マスタ!$I:$I,$AG28)="○",$E28>=L$3,$E28<EDATE(L$3,1)),"▼","")) | M28: =IF(OR($AG28=0,M$3=""),"",IF(AND(INDEX(工程マスタ!$I:$I,$AG28)="○",$E28>=M$3,$E28<EDATE(M$3,1)),"▼","")) | N28: =IF(OR($AG28=0,N$3=""),"",IF(AND(INDEX(工程マスタ!$I:$I,$AG28)="○",$E28>=N$3,$E28<EDATE(N$3,1)),"▼","")) | O28: =IF(OR($AG28=0,O$3=""),"",IF(AND(INDEX(工程マスタ!$I:$I,$AG28)="○",$E28>=O$3,$E28<EDATE(O$3,1)),"▼","")) | ... AE28: =IF(OR($AG28=0,AE$3=""),"",IF(AND(INDEX(工程マスタ!$I:$I,$AG28)="○",$E28>=AE$3,$E28<EDATE(AE$3,1)),"▼","")) | AG28: {=IFERROR(SMALL(IF(工程マスタ!$K$5:$K$154>0,ROW(工程マスタ!$C$5:$C$154)),23),0)} -> 27 | AH28: =IF($AG28=0,0,INDEX(工程マスタ!$M:$M,$AG28)) -> 46356
A29: =IF($AG29=0,"",IF(INDEX(工程マスタ!$A:$A,$AG29)="","",INDEX(工程マスタ!$A:$A,$AG29))) -> 24 | B29: =IF($AG29=0,"",IF(INDEX(工程マスタ!$B:$B,$AG29)="","",INDEX(工程マスタ!$B:$B,$AG29))) -> 外装工事 | C29: =IF($AG29=0,"",IF(INDEX(工程マスタ!$C:$C,$AG29)="","",INDEX(工程マスタ!$C:$C,$AG29))) -> サッシ・外部建具取付 | D29: =IF($AG29=0,"",IF(INDEX(工程マスタ!$D:$D,$AG29)="","",INDEX(工程マスタ!$D:$D,$AG29))) -> ▽▽サッシ | E29: =IF($AG29=0,"",IF(INDEX(工程マスタ!$E:$E,$AG29)="","",INDEX(工程マスタ!$E:$E,$AG29))) -> 46370 | F29: =IF($AG29=0,"",IF(INDEX(工程マスタ!$F:$F,$AG29)="","",INDEX(工程マスタ!$F:$F,$AG29))) -> 46395 | G29: =IF($AG29=0,"",IF(INDEX(工程マスタ!$H:$H,$AG29)="","",INDEX(工程マスタ!$H:$H,$AG29))) -> 0 | H29: =IF(OR($AG29=0,H$3=""),"",IF(AND(INDEX(工程マスタ!$I:$I,$AG29)="○",$E29>=H$3,$E29<EDATE(H$3,1)),"▼","")) | I29: =IF(OR($AG29=0,I$3=""),"",IF(AND(INDEX(工程マスタ!$I:$I,$AG29)="○",$E29>=I$3,$E29<EDATE(I$3,1)),"▼","")) | J29: =IF(OR($AG29=0,J$3=""),"",IF(AND(INDEX(工程マスタ!$I:$I,$AG29)="○",$E29>=J$3,$E29<EDATE(J$3,1)),"▼","")) | K29: =IF(OR($AG29=0,K$3=""),"",IF(AND(INDEX(工程マスタ!$I:$I,$AG29)="○",$E29>=K$3,$E29<EDATE(K$3,1)),"▼","")) | L29: =IF(OR($AG29=0,L$3=""),"",IF(AND(INDEX(工程マスタ!$I:$I,$AG29)="○",$E29>=L$3,$E29<EDATE(L$3,1)),"▼","")) | M29: =IF(OR($AG29=0,M$3=""),"",IF(AND(INDEX(工程マスタ!$I:$I,$AG29)="○",$E29>=M$3,$E29<EDATE(M$3,1)),"▼","")) | N29: =IF(OR($AG29=0,N$3=""),"",IF(AND(INDEX(工程マスタ!$I:$I,$AG29)="○",$E29>=N$3,$E29<EDATE(N$3,1)),"▼","")) | O29: =IF(OR($AG29=0,O$3=""),"",IF(AND(INDEX(工程マスタ!$I:$I,$AG29)="○",$E29>=O$3,$E29<EDATE(O$3,1)),"▼","")) | ... AE29: =IF(OR($AG29=0,AE$3=""),"",IF(AND(INDEX(工程マスタ!$I:$I,$AG29)="○",$E29>=AE$3,$E29<EDATE(AE$3,1)),"▼","")) | AG29: {=IFERROR(SMALL(IF(工程マスタ!$K$5:$K$154>0,ROW(工程マスタ!$C$5:$C$154)),24),0)} -> 28 | AH29: =IF($AG29=0,0,INDEX(工程マスタ!$M:$M,$AG29)) -> 46370
A30: =IF($AG30=0,"",IF(INDEX(工程マスタ!$A:$A,$AG30)="","",INDEX(工程マスタ!$A:$A,$AG30))) -> 25 | B30: =IF($AG30=0,"",IF(INDEX(工程マスタ!$B:$B,$AG30)="","",INDEX(工程マスタ!$B:$B,$AG30))) -> 外装工事 | C30: =IF($AG30=0,"",IF(INDEX(工程マスタ!$C:$C,$AG30)="","",INDEX(工程マスタ!$C:$C,$AG30))) -> シール・外部防水 | D30: =IF($AG30=0,"",IF(INDEX(工程マスタ!$D:$D,$AG30)="","",INDEX(工程マスタ!$D:$D,$AG30))) -> ●●防水 | E30: =IF($AG30=0,"",IF(INDEX(工程マスタ!$E:$E,$AG30)="","",INDEX(工程マスタ!$E:$E,$AG30))) -> 46392 | F30: =IF($AG30=0,"",IF(INDEX(工程マスタ!$F:$F,$AG30)="","",INDEX(工程マスタ!$F:$F,$AG30))) -> 46409 | G30: =IF($AG30=0,"",IF(INDEX(工程マスタ!$H:$H,$AG30)="","",INDEX(工程マスタ!$H:$H,$AG30))) -> 0 | H30: =IF(OR($AG30=0,H$3=""),"",IF(AND(INDEX(工程マスタ!$I:$I,$AG30)="○",$E30>=H$3,$E30<EDATE(H$3,1)),"▼","")) | I30: =IF(OR($AG30=0,I$3=""),"",IF(AND(INDEX(工程マスタ!$I:$I,$AG30)="○",$E30>=I$3,$E30<EDATE(I$3,1)),"▼","")) | J30: =IF(OR($AG30=0,J$3=""),"",IF(AND(INDEX(工程マスタ!$I:$I,$AG30)="○",$E30>=J$3,$E30<EDATE(J$3,1)),"▼","")) | K30: =IF(OR($AG30=0,K$3=""),"",IF(AND(INDEX(工程マスタ!$I:$I,$AG30)="○",$E30>=K$3,$E30<EDATE(K$3,1)),"▼","")) | L30: =IF(OR($AG30=0,L$3=""),"",IF(AND(INDEX(工程マスタ!$I:$I,$AG30)="○",$E30>=L$3,$E30<EDATE(L$3,1)),"▼","")) | M30: =IF(OR($AG30=0,M$3=""),"",IF(AND(INDEX(工程マスタ!$I:$I,$AG30)="○",$E30>=M$3,$E30<EDATE(M$3,1)),"▼","")) | N30: =IF(OR($AG30=0,N$3=""),"",IF(AND(INDEX(工程マスタ!$I:$I,$AG30)="○",$E30>=N$3,$E30<EDATE(N$3,1)),"▼","")) | O30: =IF(OR($AG30=0,O$3=""),"",IF(AND(INDEX(工程マスタ!$I:$I,$AG30)="○",$E30>=O$3,$E30<EDATE(O$3,1)),"▼","")) | ... AE30: =IF(OR($AG30=0,AE$3=""),"",IF(AND(INDEX(工程マスタ!$I:$I,$AG30)="○",$E30>=AE$3,$E30<EDATE(AE$3,1)),"▼","")) | AG30: {=IFERROR(SMALL(IF(工程マスタ!$K$5:$K$154>0,ROW(工程マスタ!$C$5:$C$154)),25),0)} -> 29 | AH30: =IF($AG30=0,0,INDEX(工程マスタ!$M:$M,$AG30)) -> 46392
